Workbook
Name SegmentaçãodeDados_CLIENTE1: #N/A
Name SegmentaçãodeDados_ID_SITE1: #N/A

Sheet PLANEJAMENTO
A1: ID SITE | B1: IDEX CONTEL | C1: CLIENTE | D1: CIDADE | E1: ESTADO | F1: LOCALIZAÇÃO | G1: SIENGE | H1: OS TOWER SYSTEM | I1: ANALISTA CONTEL | J1: VALOR EMPREITA | K1: MATERIAL | L1: FRETE/DEMAIS ITENS | M1: ETAPA | N1: STATUS | O1: ORÇAMENTO (RECEITA) (R$) | P1: CUSTOS TOTAIS (R$) | Q1: LUCRO (R$) | R1: M.C% | S1: STATUS VIABILIDADE | T1: STATUS PRAZO
A2: BR88410-A | B2: =IF(A2<>"","contel-"&TEXT(COUNTA($A$2:A2),"00"),"") -> contel-01 | C2: SBA | D2: CUJIBIM | E2: RO | F2: https://maps.app.goo.gl/Bpy8uL8ayiBD3Kdj7 | G2: 1457 | H2: 15869 | I2: PEDRO | J2: =SUM(EQUIPE!C2,EQUIPE!E2,EQUIPE!G2,EQUIPE!I2,EQUIPE!K2,EQUIPE!M2,EQUIPE!O2) -> 11006 | K2: 5615.61 | L2: 1600 | M2: =IFERROR(LEFT( IF(INDEX('ETAPA OBRA'!C:C,MATCH($B2,'ETAPA OBRA'!$B:$B,0))="x",'ETAPA OBRA'!C$1&", ","")& IF(INDEX('ETAPA OBRA'!D:D,MATCH($B2,'ETAPA OBRA'!$B:$B,0))="x",'ETAPA OBRA'!D$1&", ","")& IF(INDEX('ETAPA OBRA'!F:F,MATCH($B2,'ETAPA OBRA'!$B:$B,0))="x",'ETAPA OBRA'!F$1&", ","")& IF(INDEX('ETAPA OBRA'!G:G,MATCH($B2,'ETAPA OBRA'!$B:$B,0))="x",'ETAPA OBRA'!G$1&", ","")& IF(INDEX('ETAPA OBRA'!H:H,MATCH($B2,'ETAPA OBRA'!$B:$B,0))="x",'ETAPA OBRA'!H$1&", ","")& IF(INDEX('ETAPA OBRA'!I:I,MATCH($B2,'ETAPA OBRA'!$B:$B,0))="x",'ETAPA OBRA'!I$1&", ","")& IF(INDEX('ETAPA OBRA'!J:J,MATCH($B2,'ETAPA OBRA'!$B:$B,0))="x",'ETAPA OBRA'!J$1&", ","")& IF(INDEX('ETAPA OBRA'!K:K,MATCH($B2,'ETAPA OBRA'!$B:$B,0))="x",'ETAPA OBRA'!K$1&", ","")& IF(INDEX('ETAPA OBRA'!L:L,MATCH($B2,'ETAPA OBRA'!$B:$B,0))="x",'ETAPA OBRA'!L$1&", ","")& IF(INDEX('ETAPA OBRA'!M:M,MATCH($B2,'ETAPA OBRA'!$B:$B,0))="x",'ETAPA OBRA'!M$1&", ","")& IF(INDEX('ETAPA OBRA'!N:N,MATCH($B2,'ETAPA OBRA'!$B:$B,0))="x",'ETAPA OBRA'!N$1&", ","")& IF(INDEX('ETAPA OBRA'!O:O,MATCH($B2,'ETAPA OBRA'!$B:$B,0))="x",'ETAPA OBRA'!O$1&", ","")& IF(INDEX('ETAPA OBRA'!P:P,MATCH($B2,'ETAPA OBRA'!$B:$B,0))="x",'ETAPA OBRA'!P$1&", ","")& IF(INDEX('ETAPA OBRA'!Q:Q,MATCH($B2,'ETAPA OBRA'!$B:$B,0))="x",'ETAPA OBRA'!Q$1&", ","")& IF(INDEX('ETAPA OBRA'!R:R,MATCH($B2,'ETAPA OBRA'!$B:$B,0))="x",'ETAPA OBRA'!R$1&", ","")& IF(INDEX('ETAPA OBRA'!S:S,MATCH($B2,'ETAPA OBRA'!$B:$B,0))="x",'ETAPA OBRA'!S$1&", ","")& IF(INDEX('ETAPA OBRA'!T:T,MATCH($B2,'ETAPA OBRA'!$B:$B,0))="x",'ETAPA OBRA'!T$1&", ","")& IF(INDEX('ETAPA OBRA'!U:U,MATCH($B2,'ETAPA OBRA'!$B:$B,0))="x",'ETAPA OBRA'!U$1&", ",""),LEN( IF(INDEX('ETAPA OBRA'!C:C,MATCH($B2,'ETAPA OBRA'!$B:$B,0))="x",'ETAPA OBRA'!C$1&", ","")& IF(INDEX('ETAPA OBRA'!D:D,MATCH($B2,'ETAPA OBRA'!$B:$B,0))="x",'ETAPA OBRA'!D$1&", ","")& IF(INDEX('ETAPA OBRA'!F:F,MATCH($B2,'ETAPA OBRA'!$B:$B,0))="x",'ETAPA OBRA'!F$1&", ","")& IF(INDEX('ETAPA OBRA'!G:G,MATCH($B2,'ETAPA OBRA'!$B:$B,0))="x",'ETAPA OBRA'!G$1&", ","")& IF(INDEX('ETAPA OBRA'!H:H,MATCH($B2,'ETAPA OBRA'!$B:$B,0))="x",'ETAPA OBRA'!H$1&", ","")& IF(INDEX('ETAPA OBRA'!I:I,MATCH($B2,'ETAPA OBRA'!$B:$B,0))="x",'ETAPA OBRA'!I$1&", ","")& IF(INDEX('ETAPA OBRA'!J:J,MATCH($B2,'ETAPA OBRA'!$B:$B,0))="x",'ETAPA OBRA'!J$1&", ","")& IF(INDEX('ETAPA OBRA'!K:K,MATCH($B2,'ETAPA OBRA'!$B:$B,0))="x",'ETAPA OBRA'!K$1&", ","")& IF(INDEX('ETAPA OBRA'!L:L,MATCH($B2,'ETAPA OBRA'!$B:$B,0))="x",'ETAPA OBRA'!L$1&", ","")& IF(INDEX('ETAPA OBRA'!M:M,MATCH($B2,'ETAPA OBRA'!$B:$B,0))="x",'ETAPA OBRA'!M$1&", ","")& IF(INDEX('ETAPA OBRA'!N:N,MATCH($B2,'ETAPA OBRA'!$B:$B,0))="x",'ETAPA OBRA'!N$1&", ","")& IF(INDEX('ETAPA OBRA'!O:O,MATCH($B2,'ETAPA OBRA'!$B:$B,0))="x",'ETAPA OBRA'!O$1&", ","")& IF(INDEX('ETAPA OBRA'!P:P,MATCH($B2,'ETAPA OBRA'!$B:$B,0))="x",'ETAPA OBRA'!P$1&", ","")& IF(INDEX('ETAPA OBRA'!Q:Q,MATCH($B2,'ETAPA OBRA'!$B:$B,0))="x",'ETAPA OBRA'!Q$1&", ","")& IF(INDEX('ETAPA OBRA'!R:R,MATCH($B2,'ETAPA OBRA'!$B:$B,0))="x",'ETAPA OBRA'!R$1&", ","")& IF(INDEX('ETAPA OBRA'!S:S,MATCH($B2,'ETAPA OBRA'!$B:$B,0))="x",'ETAPA OBRA'!S$1&", ","")& IF(INDEX('ETAPA OBRA'!T:T,MATCH($B2,'ETAPA OBRA'!$B:$B,0))="x",'ETAPA OBRA'!T$1&", ","")& IF(INDEX('ETAPA OBRA'!U:U,MATCH($B2,'ETAPA OBRA'!$B:$B,0))="x",'ETAPA OBRA'!U$1&", ","") )-2),"") -> Finalizado | N2: =IF(M2="","Não iniciada", IF(ISNUMBER(FIND("Cancelada",M2)),"Cancelada", IF(ISNUMBER(FIND("Paralisada",M2)),"Paralisada", IF(ISNUMBER(FIND("Finalizado",M2)),"Finalizado", "Em andamento")))) -> Finalizado | O2: 38900.7 | P2: =SUM($J2:$L2) -> 18221.61 | Q2: =O2-P2 -> 20679.09 | R2: =IF(O2=0,0,Q2/O2) -> 0.53158658 | S2: =IF(R2>=0.2,"✅ OK - Fechar Parceiro","⚠️ Ajustar Custos (<20%)") -> ✅ OK - Fechar Parceiro | T2: =Cronograma[[#This Row],[STATUS]] -> ✅ CONCLUÍDO
A3: BR87873-R | B3: =IF(A3<>"","contel-"&TEXT(COUNTA($A$2:A3),"00"),"") -> contel-02 | C3: SBA | D3: GOIÂNIA | E3: GO | F3: https://maps.app.goo.gl/TnE3sh9j2FyxrzrFA | G3: 1527 | H3: 16078 | I3: PEDRO | J3: =SUM(EQUIPE!C3,EQUIPE!E3,EQUIPE!G3,EQUIPE!I3,EQUIPE!K3,EQUIPE!M3,EQUIPE!O3) -> 800 | K3: 1087.53 | L3: 804.64 | M3: =IFERROR(LEFT( IF(INDEX('ETAPA OBRA'!C:C,MATCH($B3,'ETAPA OBRA'!$B:$B,0))="x",'ETAPA OBRA'!C$1&", ","")& IF(INDEX('ETAPA OBRA'!D:D,MATCH($B3,'ETAPA OBRA'!$B:$B,0))="x",'ETAPA OBRA'!D$1&", ","")& IF(INDEX('ETAPA OBRA'!F:F,MATCH($B3,'ETAPA OBRA'!$B:$B,0))="x",'ETAPA OBRA'!F$1&", ","")& IF(INDEX('ETAPA OBRA'!G:G,MATCH($B3,'ETAPA OBRA'!$B:$B,0))="x",'ETAPA OBRA'!G$1&", ","")& IF(INDEX('ETAPA OBRA'!H:H,MATCH($B3,'ETAPA OBRA'!$B:$B,0))="x",'ETAPA OBRA'!H$1&", ","")& IF(INDEX('ETAPA OBRA'!I:I,MATCH($B3,'ETAPA OBRA'!$B:$B,0))="x",'ETAPA OBRA'!I$1&", ","")& IF(INDEX('ETAPA OBRA'!J:J,MATCH($B3,'ETAPA OBRA'!$B:$B,0))="x",'ETAPA OBRA'!J$1&", ","")& IF(INDEX('ETAPA OBRA'!K:K,MATCH($B3,'ETAPA OBRA'!$B:$B,0))="x",'ETAPA OBRA'!K$1&", ","")& IF(INDEX('ETAPA OBRA'!L:L,MATCH($B3,'ETAPA OBRA'!$B:$B,0))="x",'ETAPA OBRA'!L$1&", ","")& IF(INDEX('ETAPA OBRA'!M:M,MATCH($B3,'ETAPA OBRA'!$B:$B,0))="x",'ETAPA OBRA'!M$1&", ","")& IF(INDEX('ETAPA OBRA'!N:N,MATCH($B3,'ETAPA OBRA'!$B:$B,0))="x",'ETAPA OBRA'!N$1&", ","")& IF(INDEX('ETAPA OBRA'!O:O,MATCH($B3,'ETAPA OBRA'!$B:$B,0))="x",'ETAPA OBRA'!O$1&", ","")& IF(INDEX('ETAPA OBRA'!P:P,MATCH($B3,'ETAPA OBRA'!$B:$B,0))="x",'ETAPA OBRA'!P$1&", ","")& IF(INDEX('ETAPA OBRA'!Q:Q,MATCH($B3,'ETAPA OBRA'!$B:$B,0))="x",'ETAPA OBRA'!Q$1&", ","")& IF(INDEX('ETAPA OBRA'!R:R,MATCH($B3,'ETAPA OBRA'!$B:$B,0))="x",'ETAPA OBRA'!R$1&", ","")& IF(INDEX('ETAPA OBRA'!S:S,MATCH($B3,'ETAPA OBRA'!$B:$B,0))="x",'ETAPA OBRA'!S$1&", ","")& IF(INDEX('ETAPA OBRA'!T:T,MATCH($B3,'ETAPA OBRA'!$B:$B,0))="x",'ETAPA OBRA'!T$1&", ","")& IF(INDEX('ETAPA OBRA'!U:U,MATCH($B3,'ETAPA OBRA'!$B:$B,0))="x",'ETAPA OBRA'!U$1&", ",""),LEN( IF(INDEX('ETAPA OBRA'!C:C,MATCH($B3,'ETAPA OBRA'!$B:$B,0))="x",'ETAPA OBRA'!C$1&", ","")& IF(INDEX('ETAPA OBRA'!D:D,MATCH($B3,'ETAPA OBRA'!$B:$B,0))="x",'ETAPA OBRA'!D$1&", ","")& IF(INDEX('ETAPA OBRA'!F:F,MATCH($B3,'ETAPA OBRA'!$B:$B,0))="x",'ETAPA OBRA'!F$1&", ","")& IF(INDEX('ETAPA OBRA'!G:G,MATCH($B3,'ETAPA OBRA'!$B:$B,0))="x",'ETAPA OBRA'!G$1&", ","")& IF(INDEX('ETAPA OBRA'!H:H,MATCH($B3,'ETAPA OBRA'!$B:$B,0))="x",'ETAPA OBRA'!H$1&", ","")& IF(INDEX('ETAPA OBRA'!I:I,MATCH($B3,'ETAPA OBRA'!$B:$B,0))="x",'ETAPA OBRA'!I$1&", ","")& IF(INDEX('ETAPA OBRA'!J:J,MATCH($B3,'ETAPA OBRA'!$B:$B,0))="x",'ETAPA OBRA'!J$1&", ","")& IF(INDEX('ETAPA OBRA'!K:K,MATCH($B3,'ETAPA OBRA'!$B:$B,0))="x",'ETAPA OBRA'!K$1&", ","")& IF(INDEX('ETAPA OBRA'!L:L,MATCH($B3,'ETAPA OBRA'!$B:$B,0))="x",'ETAPA OBRA'!L$1&", ","")& IF(INDEX('ETAPA OBRA'!M:M,MATCH($B3,'ETAPA OBRA'!$B:$B,0))="x",'ETAPA OBRA'!M$1&", ","")& IF(INDEX('ETAPA OBRA'!N:N,MATCH($B3,'ETAPA OBRA'!$B:$B,0))="x",'ETAPA OBRA'!N$1&", ","")& IF(INDEX('ETAPA OBRA'!O:O,MATCH($B3,'ETAPA OBRA'!$B:$B,0))="x",'ETAPA OBRA'!O$1&", ","")& IF(INDEX('ETAPA OBRA'!P:P,MATCH($B3,'ETAPA OBRA'!$B:$B,0))="x",'ETAPA OBRA'!P$1&", ","")& IF(INDEX('ETAPA OBRA'!Q:Q,MATCH($B3,'ETAPA OBRA'!$B:$B,0))="x",'ETAPA OBRA'!Q$1&", ","")& IF(INDEX('ETAPA OBRA'!R:R,MATCH($B3,'ETAPA OBRA'!$B:$B,0))="x",'ETAPA OBRA'!R$1&", ","")& IF(INDEX('ETAPA OBRA'!S:S,MATCH($B3,'ETAPA OBRA'!$B:$B,0))="x",'ETAPA OBRA'!S$1&", ","")& IF(INDEX('ETAPA OBRA'!T:T,MATCH($B3,'ETAPA OBRA'!$B:$B,0))="x",'ETAPA OBRA'!T$1&", ","")& IF(INDEX('ETAPA OBRA'!U:U,MATCH($B3,'ETAPA OBRA'!$B:$B,0))="x",'ETAPA OBRA'!U$1&", ","") )-2),"") -> Finalizado | N3: =IF(M3="","Não iniciada", IF(ISNUMBER(FIND("Cancelada",M3)),"Cancelada", IF(ISNUMBER(FIND("Paralisada",M3)),"Paralisada", IF(ISNUMBER(FIND("Finalizado",M3)),"Finalizado", "Em andamento")))) -> Finalizado | O3: 5055.68 | P3: =SUM($J3:$L3) -> 2692.17 | Q3: =O3-P3 -> 2363.51 | R3: =IF(O3=0,0,Q3/O3) -> 0.46749596 | S3: =IF(R3>=0.2,"✅ OK - Fechar Parceiro","⚠️ Ajustar Custos (<20%)") -> ✅ OK - Fechar Parceiro | T3: =Cronograma[[#This Row],[STATUS]] -> ✅ CONCLUÍDO
A4: BR72396-A | B4: =IF(A4<>"","contel-"&TEXT(COUNTA($A$2:A4),"00"),"") -> contel-03 | C4: SBA | D4: PONTE NOVA | E4: MG | F4: https://maps.app.goo.gl/5FumfAyzjMHGaKJY8 | G4: 1582 | H4: 15870 | I4: DANIEL | J4: =SUM(EQUIPE!C4,EQUIPE!E4,EQUIPE!G4,EQUIPE!I4,EQUIPE!K4,EQUIPE!M4,EQUIPE!O4) -> 1300 | K4: 650 | L4: 285.3 | M4: =IFERROR(LEFT( IF(INDEX('ETAPA OBRA'!C:C,MATCH($B4,'ETAPA OBRA'!$B:$B,0))="x",'ETAPA OBRA'!C$1&", ","")& IF(INDEX('ETAPA OBRA'!D:D,MATCH($B4,'ETAPA OBRA'!$B:$B,0))="x",'ETAPA OBRA'!D$1&", ","")& IF(INDEX('ETAPA OBRA'!F:F,MATCH($B4,'ETAPA OBRA'!$B:$B,0))="x",'ETAPA OBRA'!F$1&", ","")& IF(INDEX('ETAPA OBRA'!G:G,MATCH($B4,'ETAPA OBRA'!$B:$B,0))="x",'ETAPA OBRA'!G$1&", ","")& IF(INDEX('ETAPA OBRA'!H:H,MATCH($B4,'ETAPA OBRA'!$B:$B,0))="x",'ETAPA OBRA'!H$1&", ","")& IF(INDEX('ETAPA OBRA'!I:I,MATCH($B4,'ETAPA OBRA'!$B:$B,0))="x",'ETAPA OBRA'!I$1&", ","")& IF(INDEX('ETAPA OBRA'!J:J,MATCH($B4,'ETAPA OBRA'!$B:$B,0))="x",'ETAPA OBRA'!J$1&", ","")& IF(INDEX('ETAPA OBRA'!K:K,MATCH($B4,'ETAPA OBRA'!$B:$B,0))="x",'ETAPA OBRA'!K$1&", ","")& IF(INDEX('ETAPA OBRA'!L:L,MATCH($B4,'ETAPA OBRA'!$B:$B,0))="x",'ETAPA OBRA'!L$1&", ","")& IF(INDEX('ETAPA OBRA'!M:M,MATCH($B4,'ETAPA OBRA'!$B:$B,0))="x",'ETAPA OBRA'!M$1&", ","")& IF(INDEX('ETAPA OBRA'!N:N,MATCH($B4,'ETAPA OBRA'!$B:$B,0))="x",'ETAPA OBRA'!N$1&", ","")& IF(INDEX('ETAPA OBRA'!O:O,MATCH($B4,'ETAPA OBRA'!$B:$B,0))="x",'ETAPA OBRA'!O$1&", ","")& IF(INDEX('ETAPA OBRA'!P:P,MATCH($B4,'ETAPA OBRA'!$B:$B,0))="x",'ETAPA OBRA'!P$1&", ","")& IF(INDEX('ETAPA OBRA'!Q:Q,MATCH($B4,'ETAPA OBRA'!$B:$B,0))="x",'ETAPA OBRA'!Q$1&", ","")& IF(INDEX('ETAPA OBRA'!R:R,MATCH($B4,'ETAPA OBRA'!$B:$B,0))="x",'ETAPA OBRA'!R$1&", ","")& IF(INDEX('ETAPA OBRA'!S:S,MATCH($B4,'ETAPA OBRA'!$B:$B,0))="x",'ETAPA OBRA'!S$1&", ","")& IF(INDEX('ETAPA OBRA'!T:T,MATCH($B4,'ETAPA OBRA'!$B:$B,0))="x",'ETAPA OBRA'!T$1&", ","")& IF(INDEX('ETAPA OBRA'!U:U,MATCH($B4,'ETAPA OBRA'!$B:$B,0))="x",'ETAPA OBRA'!U$1&", ",""),LEN( IF(INDEX('ETAPA OBRA'!C:C,MATCH($B4,'ETAPA OBRA'!$B:$B,0))="x",'ETAPA OBRA'!C$1&", ","")& IF(INDEX('ETAPA OBRA'!D:D,MATCH($B4,'ETAPA OBRA'!$B:$B,0))="x",'ETAPA OBRA'!D$1&", ","")& IF(INDEX('ETAPA OBRA'!F:F,MATCH($B4,'ETAPA OBRA'!$B:$B,0))="x",'ETAPA OBRA'!F$1&", ","")& IF(INDEX('ETAPA OBRA'!G:G,MATCH($B4,'ETAPA OBRA'!$B:$B,0))="x",'ETAPA OBRA'!G$1&", ","")& IF(INDEX('ETAPA OBRA'!H:H,MATCH($B4,'ETAPA OBRA'!$B:$B,0))="x",'ETAPA OBRA'!H$1&", ","")& IF(INDEX('ETAPA OBRA'!I:I,MATCH($B4,'ETAPA OBRA'!$B:$B,0))="x",'ETAPA OBRA'!I$1&", ","")& IF(INDEX('ETAPA OBRA'!J:J,MATCH($B4,'ETAPA OBRA'!$B:$B,0))="x",'ETAPA OBRA'!J$1&", ","")& IF(INDEX('ETAPA OBRA'!K:K,MATCH($B4,'ETAPA OBRA'!$B:$B,0))="x",'ETAPA OBRA'!K$1&", ","")& IF(INDEX('ETAPA OBRA'!L:L,MATCH($B4,'ETAPA OBRA'!$B:$B,0))="x",'ETAPA OBRA'!L$1&", ","")& IF(INDEX('ETAPA OBRA'!M:M,MATCH($B4,'ETAPA OBRA'!$B:$B,0))="x",'ETAPA OBRA'!M$1&", ","")& IF(INDEX('ETAPA OBRA'!N:N,MATCH($B4,'ETAPA OBRA'!$B:$B,0))="x",'ETAPA OBRA'!N$1&", ","")& IF(INDEX('ETAPA OBRA'!O:O,MATCH($B4,'ETAPA OBRA'!$B:$B,0))="x",'ETAPA OBRA'!O$1&", ","")& IF(INDEX('ETAPA OBRA'!P:P,MATCH($B4,'ETAPA OBRA'!$B:$B,0))="x",'ETAPA OBRA'!P$1&", ","")& IF(INDEX('ETAPA OBRA'!Q:Q,MATCH($B4,'ETAPA OBRA'!$B:$B,0))="x",'ETAPA OBRA'!Q$1&", ","")& IF(INDEX('ETAPA OBRA'!R:R,MATCH($B4,'ETAPA OBRA'!$B:$B,0))="x",'ETAPA OBRA'!R$1&", ","")& IF(INDEX('ETAPA OBRA'!S:S,MATCH($B4,'ETAPA OBRA'!$B:$B,0))="x",'ETAPA OBRA'!S$1&", ","")& IF(INDEX('ETAPA OBRA'!T:T,MATCH($B4,'ETAPA OBRA'!$B:$B,0))="x",'ETAPA OBRA'!T$1&", ","")& IF(INDEX('ETAPA OBRA'!U:U,MATCH($B4,'ETAPA OBRA'!$B:$B,0))="x",'ETAPA OBRA'!U$1&", ","") )-2),"") -> Finalizado | N4: =IF(M4="","Não iniciada", IF(ISNUMBER(FIND("Cancelada",M4)),"Cancelada", IF(ISNUMBER(FIND("Paralisada",M4)),"Paralisada", IF(ISNUMBER(FIND("Finalizado",M4)),"Finalizado", "Em andamento")))) -> Finalizado | O4: 9830.09 | P4: =SUM($J4:$L4) -> 2235.3 | Q4: =O4-P4 -> 7594.79 | R4: =IF(O4=0,0,Q4/O4) -> 0.77260635 | S4: =IF(R4>=0.2,"✅ OK - Fechar Parceiro","⚠️ Ajustar Custos (<20%)") -> ✅ OK - Fechar Parceiro | T4: =Cronograma[[#This Row],[STATUS]] -> ✅ CONCLUÍDO
A5: 47080009 | B5: =IF(A5<>"","contel-"&TEXT(COUNTA($A$2:A5),"00"),"") -> contel-04 | C5: IHS | D5: TIMBÓ | E5: SC | F5: https://maps.app.goo.gl/GEmH9t4Wq3nsX1C89 | G5: 1665 | H5: 4014 | I5: PEDRO | J5: =SUM(EQUIPE!C5,EQUIPE!E5,EQUIPE!G5,EQUIPE!I5,EQUIPE!K5,EQUIPE!M5,EQUIPE!O5) -> 10000 | K5: 10267.7 | L5: 853.78 | M5: =IFERROR(LEFT( IF(INDEX('ETAPA OBRA'!C:C,MATCH($B5,'ETAPA OBRA'!$B:$B,0))="x",'ETAPA OBRA'!C$1&", ","")& IF(INDEX('ETAPA OBRA'!D:D,MATCH($B5,'ETAPA OBRA'!$B:$B,0))="x",'ETAPA OBRA'!D$1&", ","")& IF(INDEX('ETAPA OBRA'!F:F,MATCH($B5,'ETAPA OBRA'!$B:$B,0))="x",'ETAPA OBRA'!F$1&", ","")& IF(INDEX('ETAPA OBRA'!G:G,MATCH($B5,'ETAPA OBRA'!$B:$B,0))="x",'ETAPA OBRA'!G$1&", ","")& IF(INDEX('ETAPA OBRA'!H:H,MATCH($B5,'ETAPA OBRA'!$B:$B,0))="x",'ETAPA OBRA'!H$1&", ","")& IF(INDEX('ETAPA OBRA'!I:I,MATCH($B5,'ETAPA OBRA'!$B:$B,0))="x",'ETAPA OBRA'!I$1&", ","")& IF(INDEX('ETAPA OBRA'!J:J,MATCH($B5,'ETAPA OBRA'!$B:$B,0))="x",'ETAPA OBRA'!J$1&", ","")& IF(INDEX('ETAPA OBRA'!K:K,MATCH($B5,'ETAPA OBRA'!$B:$B,0))="x",'ETAPA OBRA'!K$1&", ","")& IF(INDEX('ETAPA OBRA'!L:L,MATCH($B5,'ETAPA OBRA'!$B:$B,0))="x",'ETAPA OBRA'!L$1&", ","")& IF(INDEX('ETAPA OBRA'!M:M,MATCH($B5,'ETAPA OBRA'!$B:$B,0))="x",'ETAPA OBRA'!M$1&", ","")& IF(INDEX('ETAPA OBRA'!N:N,MATCH($B5,'ETAPA OBRA'!$B:$B,0))="x",'ETAPA OBRA'!N$1&", ","")& IF(INDEX('ETAPA OBRA'!O:O,MATCH($B5,'ETAPA OBRA'!$B:$B,0))="x",'ETAPA OBRA'!O$1&", ","")& IF(INDEX('ETAPA OBRA'!P:P,MATCH($B5,'ETAPA OBRA'!$B:$B,0))="x",'ETAPA OBRA'!P$1&", ","")& IF(INDEX('ETAPA OBRA'!Q:Q,MATCH($B5,'ETAPA OBRA'!$B:$B,0))="x",'ETAPA OBRA'!Q$1&", ","")& IF(INDEX('ETAPA OBRA'!R:R,MATCH($B5,'ETAPA OBRA'!$B:$B,0))="x",'ETAPA OBRA'!R$1&", ","")& IF(INDEX('ETAPA OBRA'!S:S,MATCH($B5,'ETAPA OBRA'!$B:$B,0))="x",'ETAPA OBRA'!S$1&", ","")& IF(INDEX('ETAPA OBRA'!T:T,MATCH($B5,'ETAPA OBRA'!$B:$B,0))="x",'ETAPA OBRA'!T$1&", ","")& IF(INDEX('ETAPA OBRA'!U:U,MATCH($B5,'ETAPA OBRA'!$B:$B,0))="x",'ETAPA OBRA'!U$1&", ",""),LEN( IF(INDEX('ETAPA OBRA'!C:C,MATCH($B5,'ETAPA OBRA'!$B:$B,0))="x",'ETAPA OBRA'!C$1&", ","")& IF(INDEX('ETAPA OBRA'!D:D,MATCH($B5,'ETAPA OBRA'!$B:$B,0))="x",'ETAPA OBRA'!D$1&", ","")& IF(INDEX('ETAPA OBRA'!F:F,MATCH($B5,'ETAPA OBRA'!$B:$B,0))="x",'ETAPA OBRA'!F$1&", ","")& IF(INDEX('ETAPA OBRA'!G:G,MATCH($B5,'ETAPA OBRA'!$B:$B,0))="x",'ETAPA OBRA'!G$1&", ","")& IF(INDEX('ETAPA OBRA'!H:H,MATCH($B5,'ETAPA OBRA'!$B:$B,0))="x",'ETAPA OBRA'!H$1&", ","")& IF(INDEX('ETAPA OBRA'!I:I,MATCH($B5,'ETAPA OBRA'!$B:$B,0))="x",'ETAPA OBRA'!I$1&", ","")& IF(INDEX('ETAPA OBRA'!J:J,MATCH($B5,'ETAPA OBRA'!$B:$B,0))="x",'ETAPA OBRA'!J$1&", ","")& IF(INDEX('ETAPA OBRA'!K:K,MATCH($B5,'ETAPA OBRA'!$B:$B,0))="x",'ETAPA OBRA'!K$1&", ","")& IF(INDEX('ETAPA OBRA'!L:L,MATCH($B5,'ETAPA OBRA'!$B:$B,0))="x",'ETAPA OBRA'!L$1&", ","")& IF(INDEX('ETAPA OBRA'!M:M,MATCH($B5,'ETAPA OBRA'!$B:$B,0))="x",'ETAPA OBRA'!M$1&", ","")& IF(INDEX('ETAPA OBRA'!N:N,MATCH($B5,'ETAPA OBRA'!$B:$B,0))="x",'ETAPA OBRA'!N$1&", ","")& IF(INDEX('ETAPA OBRA'!O:O,MATCH($B5,'ETAPA OBRA'!$B:$B,0))="x",'ETAPA OBRA'!O$1&", ","")& IF(INDEX('ETAPA OBRA'!P:P,MATCH($B5,'ETAPA OBRA'!$B:$B,0))="x",'ETAPA OBRA'!P$1&", ","")& IF(INDEX('ETAPA OBRA'!Q:Q,MATCH($B5,'ETAPA OBRA'!$B:$B,0))="x",'ETAPA OBRA'!Q$1&", ","")& IF(INDEX('ETAPA OBRA'!R:R,MATCH($B5,'ETAPA OBRA'!$B:$B,0))="x",'ETAPA OBRA'!R$1&", ","")& IF(INDEX('ETAPA OBRA'!S:S,MATCH($B5,'ETAPA OBRA'!$B:$B,0))="x",'ETAPA OBRA'!S$1&", ","")& IF(INDEX('ETAPA OBRA'!T:T,MATCH($B5,'ETAPA OBRA'!$B:$B,0))="x",'ETAPA OBRA'!T$1&", ","")& IF(INDEX('ETAPA OBRA'!U:U,MATCH($B5,'ETAPA OBRA'!$B:$B,0))="x",'ETAPA OBRA'!U$1&", ","") )-2),"") -> Finalizado | N5: =IF(M5="","Não iniciada", IF(ISNUMBER(FIND("Cancelada",M5)),"Cancelada", IF(ISNUMBER(FIND("Paralisada",M5)),"Paralisada", IF(ISNUMBER(FIND("Finalizado",M5)),"Finalizado", "Em andamento")))) -> Finalizado | O5: 119837.4 | P5: =SUM($J5:$L5) -> 21121.48 | Q5: =O5-P5 -> 98715.92 | R5: =IF(O5=0,0,Q5/O5) -> 0.82374885 | S5: =IF(R5>=0.2,"✅ OK - Fechar Parceiro","⚠️ Ajustar Custos (<20%)") -> ✅ OK - Fechar Parceiro | T5: =Cronograma[[#This Row],[STATUS]] -> ✅ CONCLUÍDO
A6: 38050011 | B6: =IF(A6<>"","contel-"&TEXT(COUNTA($A$2:A6),"00"),"") -> contel-05 | C6: IHS | D6: TRÊS MARIAS | E6: MG | F6: https://maps.app.goo.gl/NzQT4s3F2LTnY1nW9 | G6: 1678 | H6: 12763 | I6: PEDRO | J6: =SUM(EQUIPE!C6,EQUIPE!E6,EQUIPE!G6,EQUIPE!I6,EQUIPE!K6,EQUIPE!M6,EQUIPE!O6) -> 0 | K6: 24882.24 | L6: 0 | M6: =IFERROR(LEFT( IF(INDEX('ETAPA OBRA'!C:C,MATCH($B6,'ETAPA OBRA'!$B:$B,0))="x",'ETAPA OBRA'!C$1&", ","")& IF(INDEX('ETAPA OBRA'!D:D,MATCH($B6,'ETAPA OBRA'!$B:$B,0))="x",'ETAPA OBRA'!D$1&", ","")& IF(INDEX('ETAPA OBRA'!F:F,MATCH($B6,'ETAPA OBRA'!$B:$B,0))="x",'ETAPA OBRA'!F$1&", ","")& IF(INDEX('ETAPA OBRA'!G:G,MATCH($B6,'ETAPA OBRA'!$B:$B,0))="x",'ETAPA OBRA'!G$1&", ","")& IF(INDEX('ETAPA OBRA'!H:H,MATCH($B6,'ETAPA OBRA'!$B:$B,0))="x",'ETAPA OBRA'!H$1&", ","")& IF(INDEX('ETAPA OBRA'!I:I,MATCH($B6,'ETAPA OBRA'!$B:$B,0))="x",'ETAPA OBRA'!I$1&", ","")& IF(INDEX('ETAPA OBRA'!J:J,MATCH($B6,'ETAPA OBRA'!$B:$B,0))="x",'ETAPA OBRA'!J$1&", ","")& IF(INDEX('ETAPA OBRA'!K:K,MATCH($B6,'ETAPA OBRA'!$B:$B,0))="x",'ETAPA OBRA'!K$1&", ","")& IF(INDEX('ETAPA OBRA'!L:L,MATCH($B6,'ETAPA OBRA'!$B:$B,0))="x",'ETAPA OBRA'!L$1&", ","")& IF(INDEX('ETAPA OBRA'!M:M,MATCH($B6,'ETAPA OBRA'!$B:$B,0))="x",'ETAPA OBRA'!M$1&", ","")& IF(INDEX('ETAPA OBRA'!N:N,MATCH($B6,'ETAPA OBRA'!$B:$B,0))="x",'ETAPA OBRA'!N$1&", ","")& IF(INDEX('ETAPA OBRA'!O:O,MATCH($B6,'ETAPA OBRA'!$B:$B,0))="x",'ETAPA OBRA'!O$1&", ","")& IF(INDEX('ETAPA OBRA'!P:P,MATCH($B6,'ETAPA OBRA'!$B:$B,0))="x",'ETAPA OBRA'!P$1&", ","")& IF(INDEX('ETAPA OBRA'!Q:Q,MATCH($B6,'ETAPA OBRA'!$B:$B,0))="x",'ETAPA OBRA'!Q$1&", ","")& IF(INDEX('ETAPA OBRA'!R:R,MATCH($B6,'ETAPA OBRA'!$B:$B,0))="x",'ETAPA OBRA'!R$1&", ","")& IF(INDEX('ETAPA OBRA'!S:S,MATCH($B6,'ETAPA OBRA'!$B:$B,0))="x",'ETAPA OBRA'!S$1&", ","")& IF(INDEX('ETAPA OBRA'!T:T,MATCH($B6,'ETAPA OBRA'!$B:$B,0))="x",'ETAPA OBRA'!T$1&", ","")& IF(INDEX('ETAPA OBRA'!U:U,MATCH($B6,'ETAPA OBRA'!$B:$B,0))="x",'ETAPA OBRA'!U$1&", ",""),LEN( IF(INDEX('ETAPA OBRA'!C:C,MATCH($B6,'ETAPA OBRA'!$B:$B,0))="x",'ETAPA OBRA'!C$1&", ","")& IF(INDEX('ETAPA OBRA'!D:D,MATCH($B6,'ETAPA OBRA'!$B:$B,0))="x",'ETAPA OBRA'!D$1&", ","")& IF(INDEX('ETAPA OBRA'!F:F,MATCH($B6,'ETAPA OBRA'!$B:$B,0))="x",'ETAPA OBRA'!F$1&", ","")& IF(INDEX('ETAPA OBRA'!G:G,MATCH($B6,'ETAPA OBRA'!$B:$B,0))="x",'ETAPA OBRA'!G$1&", ","")& IF(INDEX('ETAPA OBRA'!H:H,MATCH($B6,'ETAPA OBRA'!$B:$B,0))="x",'ETAPA OBRA'!H$1&", ","")& IF(INDEX('ETAPA OBRA'!I:I,MATCH($B6,'ETAPA OBRA'!$B:$B,0))="x",'ETAPA OBRA'!I$1&", ","")& IF(INDEX('ETAPA OBRA'!J:J,MATCH($B6,'ETAPA OBRA'!$B:$B,0))="x",'ETAPA OBRA'!J$1&", ","")& IF(INDEX('ETAPA OBRA'!K:K,MATCH($B6,'ETAPA OBRA'!$B:$B,0))="x",'ETAPA OBRA'!K$1&", ","")& IF(INDEX('ETAPA OBRA'!L:L,MATCH($B6,'ETAPA OBRA'!$B:$B,0))="x",'ETAPA OBRA'!L$1&", ","")& IF(INDEX('ETAPA OBRA'!M:M,MATCH($B6,'ETAPA OBRA'!$B:$B,0))="x",'ETAPA OBRA'!M$1&", ","")& IF(INDEX('ETAPA OBRA'!N:N,MATCH($B6,'ETAPA OBRA'!$B:$B,0))="x",'ETAPA OBRA'!N$1&", ","")& IF(INDEX('ETAPA OBRA'!O:O,MATCH($B6,'ETAPA OBRA'!$B:$B,0))="x",'ETAPA OBRA'!O$1&", ","")& IF(INDEX('ETAPA OBRA'!P:P,MATCH($B6,'ETAPA OBRA'!$B:$B,0))="x",'ETAPA OBRA'!P$1&", ","")& IF(INDEX('ETAPA OBRA'!Q:Q,MATCH($B6,'ETAPA OBRA'!$B:$B,0))="x",'ETAPA OBRA'!Q$1&", ","")& IF(INDEX('ETAPA OBRA'!R:R,MATCH($B6,'ETAPA OBRA'!$B:$B,0))="x",'ETAPA OBRA'!R$1&", ","")& IF(INDEX('ETAPA OBRA'!S:S,MATCH($B6,'ETAPA OBRA'!$B:$B,0))="x",'ETAPA OBRA'!S$1&", ","")& IF(INDEX('ETAPA OBRA'!T:T,MATCH($B6,'ETAPA OBRA'!$B:$B,0))="x",'ETAPA OBRA'!T$1&", ","")& IF(INDEX('ETAPA OBRA'!U:U,MATCH($B6,'ETAPA OBRA'!$B:$B,0))="x",'ETAPA OBRA'!U$1&", ","") )-2),"") -> Laudo de verticalidade, Envio RFI | N6: =IF(M6="","Não iniciada", IF(ISNUMBER(FIND("Cancelada",M6)),"Cancelada", IF(ISNUMBER(FIND("Paralisada",M6)),"Paralisada", IF(ISNUMBER(FIND("Finalizado",M6)),"Finalizado", "Em andamento")))) -> Em andamento | O6: 89264 | P6: =SUM($J6:$L6) -> 24882.24 | Q6: =O6-P6 -> 64381.76 | R6: =IF(O6=0,0,Q6/O6) -> 0.72125112 | S6: =IF(R6>=0.2,"✅ OK - Fechar Parceiro","⚠️ Ajustar Custos (<20%)") -> ✅ OK - Fechar Parceiro | T6: =Cronograma[[#This Row],[STATUS]] -> ⏰ ATRASADO
A7: 38050012 | B7: =IF(A7<>"","contel-"&TEXT(COUNTA($A$2:A7),"00"),"") -> contel-06 | C7: IHS | D7: TRÊS MARIAS | E7: MG | F7: https://maps.app.goo.gl/FhvvJXRy7LcsaaeZ7 | G7: 1679 | H7: 12764 | I7: PEDRO | J7: =SUM(EQUIPE!C7,EQUIPE!E7,EQUIPE!G7,EQUIPE!I7,EQUIPE!K7,EQUIPE!M7,EQUIPE!O7) -> 0 | K7: 16990.4 | L7: 11517.19 | M7: =IFERROR(LEFT( IF(INDEX('ETAPA OBRA'!C:C,MATCH($B7,'ETAPA OBRA'!$B:$B,0))="x",'ETAPA OBRA'!C$1&", ","")& IF(INDEX('ETAPA OBRA'!D:D,MATCH($B7,'ETAPA OBRA'!$B:$B,0))="x",'ETAPA OBRA'!D$1&", ","")& IF(INDEX('ETAPA OBRA'!F:F,MATCH($B7,'ETAPA OBRA'!$B:$B,0))="x",'ETAPA OBRA'!F$1&", ","")& IF(INDEX('ETAPA OBRA'!G:G,MATCH($B7,'ETAPA OBRA'!$B:$B,0))="x",'ETAPA OBRA'!G$1&", ","")& IF(INDEX('ETAPA OBRA'!H:H,MATCH($B7,'ETAPA OBRA'!$B:$B,0))="x",'ETAPA OBRA'!H$1&", ","")& IF(INDEX('ETAPA OBRA'!I:I,MATCH($B7,'ETAPA OBRA'!$B:$B,0))="x",'ETAPA OBRA'!I$1&", ","")& IF(INDEX('ETAPA OBRA'!J:J,MATCH($B7,'ETAPA OBRA'!$B:$B,0))="x",'ETAPA OBRA'!J$1&", ","")& IF(INDEX('ETAPA OBRA'!K:K,MATCH($B7,'ETAPA OBRA'!$B:$B,0))="x",'ETAPA OBRA'!K$1&", ","")& IF(INDEX('ETAPA OBRA'!L:L,MATCH($B7,'ETAPA OBRA'!$B:$B,0))="x",'ETAPA OBRA'!L$1&", ","")& IF(INDEX('ETAPA OBRA'!M:M,MATCH($B7,'ETAPA OBRA'!$B:$B,0))="x",'ETAPA OBRA'!M$1&", ","")& IF(INDEX('ETAPA OBRA'!N:N,MATCH($B7,'ETAPA OBRA'!$B:$B,0))="x",'ETAPA OBRA'!N$1&", ","")& IF(INDEX('ETAPA OBRA'!O:O,MATCH($B7,'ETAPA OBRA'!$B:$B,0))="x",'ETAPA OBRA'!O$1&", ","")& IF(INDEX('ETAPA OBRA'!P:P,MATCH($B7,'ETAPA OBRA'!$B:$B,0))="x",'ETAPA OBRA'!P$1&", ","")& IF(INDEX('ETAPA OBRA'!Q:Q,MATCH($B7,'ETAPA OBRA'!$B:$B,0))="x",'ETAPA OBRA'!Q$1&", ","")& IF(INDEX('ETAPA OBRA'!R:R,MATCH($B7,'ETAPA OBRA'!$B:$B,0))="x",'ETAPA OBRA'!R$1&", ","")& IF(INDEX('ETAPA OBRA'!S:S,MATCH($B7,'ETAPA OBRA'!$B:$B,0))="x",'ETAPA OBRA'!S$1&", ","")& IF(INDEX('ETAPA OBRA'!T:T,MATCH($B7,'ETAPA OBRA'!$B:$B,0))="x",'ETAPA OBRA'!T$1&", ","")& IF(INDEX('ETAPA OBRA'!U:U,MATCH($B7,'ETAPA OBRA'!$B:$B,0))="x",'ETAPA OBRA'!U$1&", ",""),LEN( IF(INDEX('ETAPA OBRA'!C:C,MATCH($B7,'ETAPA OBRA'!$B:$B,0))="x",'ETAPA OBRA'!C$1&", ","")& IF(INDEX('ETAPA OBRA'!D:D,MATCH($B7,'ETAPA OBRA'!$B:$B,0))="x",'ETAPA OBRA'!D$1&", ","")& IF(INDEX('ETAPA OBRA'!F:F,MATCH($B7,'ETAPA OBRA'!$B:$B,0))="x",'ETAPA OBRA'!F$1&", ","")& IF(INDEX('ETAPA OBRA'!G:G,MATCH($B7,'ETAPA OBRA'!$B:$B,0))="x",'ETAPA OBRA'!G$1&", ","")& IF(INDEX('ETAPA OBRA'!H:H,MATCH($B7,'ETAPA OBRA'!$B:$B,0))="x",'ETAPA OBRA'!H$1&", ","")& IF(INDEX('ETAPA OBRA'!I:I,MATCH($B7,'ETAPA OBRA'!$B:$B,0))="x",'ETAPA OBRA'!I$1&", ","")& IF(INDEX('ETAPA OBRA'!J:J,MATCH($B7,'ETAPA OBRA'!$B:$B,0))="x",'ETAPA OBRA'!J$1&", ","")& IF(INDEX('ETAPA OBRA'!K:K,MATCH($B7,'ETAPA OBRA'!$B:$B,0))="x",'ETAPA OBRA'!K$1&", ","")& IF(INDEX('ETAPA OBRA'!L:L,MATCH($B7,'ETAPA OBRA'!$B:$B,0))="x",'ETAPA OBRA'!L$1&", ","")& IF(INDEX('ETAPA OBRA'!M:M,MATCH($B7,'ETAPA OBRA'!$B:$B,0))="x",'ETAPA OBRA'!M$1&", ","")& IF(INDEX('ETAPA OBRA'!N:N,MATCH($B7,'ETAPA OBRA'!$B:$B,0))="x",'ETAPA OBRA'!N$1&", ","")& IF(INDEX('ETAPA OBRA'!O:O,MATCH($B7,'ETAPA OBRA'!$B:$B,0))="x",'ETAPA OBRA'!O$1&", ","")& IF(INDEX('ETAPA OBRA'!P:P,MATCH($B7,'ETAPA OBRA'!$B:$B,0))="x",'ETAPA OBRA'!P$1&", ","")& IF(INDEX('ETAPA OBRA'!Q:Q,MATCH($B7,'ETAPA OBRA'!$B:$B,0))="x",'ETAPA OBRA'!Q$1&", ","")& IF(INDEX('ETAPA OBRA'!R:R,MATCH($B7,'ETAPA OBRA'!$B:$B,0))="x",'ETAPA OBRA'!R$1&", ","")& IF(INDEX('ETAPA OBRA'!S:S,MATCH($B7,'ETAPA OBRA'!$B:$B,0))="x",'ETAPA OBRA'!S$1&", ","")& IF(INDEX('ETAPA OBRA'!T:T,MATCH($B7,'ETAPA OBRA'!$B:$B,0))="x",'ETAPA OBRA'!T$1&", ","")& IF(INDEX('ETAPA OBRA'!U:U,MATCH($B7,'ETAPA OBRA'!$B:$B,0))="x",'ETAPA OBRA'!U$1&", ","") )-2),"") -> Laudo de verticalidade, Envio RFI | N7: =IF(M7="","Não iniciada", IF(ISNUMBER(FIND("Cancelada",M7)),"Cancelada", IF(ISNUMBER(FIND("Paralisada",M7)),"Paralisada", IF(ISNUMBER(FIND("Finalizado",M7)),"Finalizado", "Em andamento")))) -> Em andamento | O7: 89264 | P7: =SUM($J7:$L7) -> 28507.59 | Q7: =O7-P7 -> 60756.41 | R7: =IF(O7=0,0,Q7/O7) -> 0.68063732 | S7: =IF(R7>=0.2,"✅ OK - Fechar Parceiro","⚠️ Ajustar Custos (<20%)") -> ✅ OK - Fechar Parceiro | T7: =Cronograma[[#This Row],[STATUS]] -> ⏰ ATRASADO
A8: 33050064 | B8: =IF(A8<>"","contel-"&TEXT(COUNTA($A$2:A8),"00"),"") -> contel-07 | C8: IHS | D8: POCRANE | E8: MG | F8: https://maps.app.goo.gl/3RSxxC8eTf2D8Cmh8 | G8: 1680 | H8: 12765 | I8: PEDRO | J8: =SUM(EQUIPE!C8,EQUIPE!E8,EQUIPE!G8,EQUIPE!I8,EQUIPE!K8,EQUIPE!M8,EQUIPE!O8) -> 26000 | K8: 15959.77 | L8: 13697.3 | M8: =IFERROR(LEFT( IF(INDEX('ETAPA OBRA'!C:C,MATCH($B8,'ETAPA OBRA'!$B:$B,0))="x",'ETAPA OBRA'!C$1&", ","")& IF(INDEX('ETAPA OBRA'!D:D,MATCH($B8,'ETAPA OBRA'!$B:$B,0))="x",'ETAPA OBRA'!D$1&", ","")& IF(INDEX('ETAPA OBRA'!F:F,MATCH($B8,'ETAPA OBRA'!$B:$B,0))="x",'ETAPA OBRA'!F$1&", ","")& IF(INDEX('ETAPA OBRA'!G:G,MATCH($B8,'ETAPA OBRA'!$B:$B,0))="x",'ETAPA OBRA'!G$1&", ","")& IF(INDEX('ETAPA OBRA'!H:H,MATCH($B8,'ETAPA OBRA'!$B:$B,0))="x",'ETAPA OBRA'!H$1&", ","")& IF(INDEX('ETAPA OBRA'!I:I,MATCH($B8,'ETAPA OBRA'!$B:$B,0))="x",'ETAPA OBRA'!I$1&", ","")& IF(INDEX('ETAPA OBRA'!J:J,MATCH($B8,'ETAPA OBRA'!$B:$B,0))="x",'ETAPA OBRA'!J$1&", ","")& IF(INDEX('ETAPA OBRA'!K:K,MATCH($B8,'ETAPA OBRA'!$B:$B,0))="x",'ETAPA OBRA'!K$1&", ","")& IF(INDEX('ETAPA OBRA'!L:L,MATCH($B8,'ETAPA OBRA'!$B:$B,0))="x",'ETAPA OBRA'!L$1&", ","")& IF(INDEX('ETAPA OBRA'!M:M,MATCH($B8,'ETAPA OBRA'!$B:$B,0))="x",'ETAPA OBRA'!M$1&", ","")& IF(INDEX('ETAPA OBRA'!N:N,MATCH($B8,'ETAPA OBRA'!$B:$B,0))="x",'ETAPA OBRA'!N$1&", ","")& IF(INDEX('ETAPA OBRA'!O:O,MATCH($B8,'ETAPA OBRA'!$B:$B,0))="x",'ETAPA OBRA'!O$1&", ","")& IF(INDEX('ETAPA OBRA'!P:P,MATCH($B8,'ETAPA OBRA'!$B:$B,0))="x",'ETAPA OBRA'!P$1&", ","")& IF(INDEX('ETAPA OBRA'!Q:Q,MATCH($B8,'ETAPA OBRA'!$B:$B,0))="x",'ETAPA OBRA'!Q$1&", ","")& IF(INDEX('ETAPA OBRA'!R:R,MATCH($B8,'ETAPA OBRA'!$B:$B,0))="x",'ETAPA OBRA'!R$1&", ","")& IF(INDEX('ETAPA OBRA'!S:S,MATCH($B8,'ETAPA OBRA'!$B:$B,0))="x",'ETAPA OBRA'!S$1&", ","")& IF(INDEX('ETAPA OBRA'!T:T,MATCH($B8,'ETAPA OBRA'!$B:$B,0))="x",'ETAPA OBRA'!T$1&", ","")& IF(INDEX('ETAPA OBRA'!U:U,MATCH($B8,'ETAPA OBRA'!$B:$B,0))="x",'ETAPA OBRA'!U$1&", ",""),LEN( IF(INDEX('ETAPA OBRA'!C:C,MATCH($B8,'ETAPA OBRA'!$B:$B,0))="x",'ETAPA OBRA'!C$1&", ","")& IF(INDEX('ETAPA OBRA'!D:D,MATCH($B8,'ETAPA OBRA'!$B:$B,0))="x",'ETAPA OBRA'!D$1&", ","")& IF(INDEX('ETAPA OBRA'!F:F,MATCH($B8,'ETAPA OBRA'!$B:$B,0))="x",'ETAPA OBRA'!F$1&", ","")& IF(INDEX('ETAPA OBRA'!G:G,MATCH($B8,'ETAPA OBRA'!$B:$B,0))="x",'ETAPA OBRA'!G$1&", ","")& IF(INDEX('ETAPA OBRA'!H:H,MATCH($B8,'ETAPA OBRA'!$B:$B,0))="x",'ETAPA OBRA'!H$1&", ","")& IF(INDEX('ETAPA OBRA'!I:I,MATCH($B8,'ETAPA OBRA'!$B:$B,0))="x",'ETAPA OBRA'!I$1&", ","")& IF(INDEX('ETAPA OBRA'!J:J,MATCH($B8,'ETAPA OBRA'!$B:$B,0))="x",'ETAPA OBRA'!J$1&", ","")& IF(INDEX('ETAPA OBRA'!K:K,MATCH($B8,'ETAPA OBRA'!$B:$B,0))="x",'ETAPA OBRA'!K$1&", ","")& IF(INDEX('ETAPA OBRA'!L:L,MATCH($B8,'ETAPA OBRA'!$B:$B,0))="x",'ETAPA OBRA'!L$1&", ","")& IF(INDEX('ETAPA OBRA'!M:M,MATCH($B8,'ETAPA OBRA'!$B:$B,0))="x",'ETAPA OBRA'!M$1&", ","")& IF(INDEX('ETAPA OBRA'!N:N,MATCH($B8,'ETAPA OBRA'!$B:$B,0))="x",'ETAPA OBRA'!N$1&", ","")& IF(INDEX('ETAPA OBRA'!O:O,MATCH($B8,'ETAPA OBRA'!$B:$B,0))="x",'ETAPA OBRA'!O$1&", ","")& IF(INDEX('ETAPA OBRA'!P:P,MATCH($B8,'ETAPA OBRA'!$B:$B,0))="x",'ETAPA OBRA'!P$1&", ","")& IF(INDEX('ETAPA OBRA'!Q:Q,MATCH($B8,'ETAPA OBRA'!$B:$B,0))="x",'ETAPA OBRA'!Q$1&", ","")& IF(INDEX('ETAPA OBRA'!R:R,MATCH($B8,'ETAPA OBRA'!$B:$B,0))="x",'ETAPA OBRA'!R$1&", ","")& IF(INDEX('ETAPA OBRA'!S:S,MATCH($B8,'ETAPA OBRA'!$B:$B,0))="x",'ETAPA OBRA'!S$1&", ","")& IF(INDEX('ETAPA OBRA'!T:T,MATCH($B8,'ETAPA OBRA'!$B:$B,0))="x",'ETAPA OBRA'!T$1&", ","")& IF(INDEX('ETAPA OBRA'!U:U,MATCH($B8,'ETAPA OBRA'!$B:$B,0))="x",'ETAPA OBRA'!U$1&", ","") )-2),"") -> Laudo de verticalidade, Envio RFI | N8: =IF(M8="","Não iniciada", IF(ISNUMBER(FIND("Cancelada",M8)),"Cancelada", IF(ISNUMBER(FIND("Paralisada",M8)),"Paralisada", IF(ISNUMBER(FIND("Finalizado",M8)),"Finalizado", "Em andamento")))) -> Em andamento | O8: 89264 | P8: =SUM($J8:$L8) -> 55657.07 | Q8: =O8-P8 -> 33606.93 | R8: =IF(O8=0,0,Q8/O8) -> 0.37648918 | S8: =IF(R8>=0.2,"✅ OK - Fechar Parceiro","⚠️ Ajustar Custos (<20%)") -> ✅ OK - Fechar Parceiro | T8: =Cronograma[[#This Row],[STATUS]] -> ⏰ ATRASADO
A9: 38050013 | B9: =IF(A9<>"","contel-"&TEXT(COUNTA($A$2:A9),"00"),"") -> contel-08 | C9: IHS | D9: SÃO GONÇALO DO ABAETÉ | E9: MG | F9: https://maps.app.goo.gl/mHsLofcw4vKxRipE6 | G9: 1681 | H9: 12766 | I9: PEDRO | J9: =SUM(EQUIPE!C9,EQUIPE!E9,EQUIPE!G9,EQUIPE!I9,EQUIPE!K9,EQUIPE!M9,EQUIPE!O9) -> 27500 | K9: 27453.33 | L9: 1490 | M9: =IFERROR(LEFT( IF(INDEX('ETAPA OBRA'!C:C,MATCH($B9,'ETAPA OBRA'!$B:$B,0))="x",'ETAPA OBRA'!C$1&", ","")& IF(INDEX('ETAPA OBRA'!D:D,MATCH($B9,'ETAPA OBRA'!$B:$B,0))="x",'ETAPA OBRA'!D$1&", ","")& IF(INDEX('ETAPA OBRA'!F:F,MATCH($B9,'ETAPA OBRA'!$B:$B,0))="x",'ETAPA OBRA'!F$1&", ","")& IF(INDEX('ETAPA OBRA'!G:G,MATCH($B9,'ETAPA OBRA'!$B:$B,0))="x",'ETAPA OBRA'!G$1&", ","")& IF(INDEX('ETAPA OBRA'!H:H,MATCH($B9,'ETAPA OBRA'!$B:$B,0))="x",'ETAPA OBRA'!H$1&", ","")& IF(INDEX('ETAPA OBRA'!I:I,MATCH($B9,'ETAPA OBRA'!$B:$B,0))="x",'ETAPA OBRA'!I$1&", ","")& IF(INDEX('ETAPA OBRA'!J:J,MATCH($B9,'ETAPA OBRA'!$B:$B,0))="x",'ETAPA OBRA'!J$1&", ","")& IF(INDEX('ETAPA OBRA'!K:K,MATCH($B9,'ETAPA OBRA'!$B:$B,0))="x",'ETAPA OBRA'!K$1&", ","")& IF(INDEX('ETAPA OBRA'!L:L,MATCH($B9,'ETAPA OBRA'!$B:$B,0))="x",'ETAPA OBRA'!L$1&", ","")& IF(INDEX('ETAPA OBRA'!M:M,MATCH($B9,'ETAPA OBRA'!$B:$B,0))="x",'ETAPA OBRA'!M$1&", ","")& IF(INDEX('ETAPA OBRA'!N:N,MATCH($B9,'ETAPA OBRA'!$B:$B,0))="x",'ETAPA OBRA'!N$1&", ","")& IF(INDEX('ETAPA OBRA'!O:O,MATCH($B9,'ETAPA OBRA'!$B:$B,0))="x",'ETAPA OBRA'!O$1&", ","")& IF(INDEX('ETAPA OBRA'!P:P,MATCH($B9,'ETAPA OBRA'!$B:$B,0))="x",'ETAPA OBRA'!P$1&", ","")& IF(INDEX('ETAPA OBRA'!Q:Q,MATCH($B9,'ETAPA OBRA'!$B:$B,0))="x",'ETAPA OBRA'!Q$1&", ","")& IF(INDEX('ETAPA OBRA'!R:R,MATCH($B9,'ETAPA OBRA'!$B:$B,0))="x",'ETAPA OBRA'!R$1&", ","")& IF(INDEX('ETAPA OBRA'!S:S,MATCH($B9,'ETAPA OBRA'!$B:$B,0))="x",'ETAPA OBRA'!S$1&", ","")& IF(INDEX('ETAPA OBRA'!T:T,MATCH($B9,'ETAPA OBRA'!$B:$B,0))="x",'ETAPA OBRA'!T$1&", ","")& IF(INDEX('ETAPA OBRA'!U:U,MATCH($B9,'ETAPA OBRA'!$B:$B,0))="x",'ETAPA OBRA'!U$1&", ",""),LEN( IF(INDEX('ETAPA OBRA'!C:C,MATCH($B9,'ETAPA OBRA'!$B:$B,0))="x",'ETAPA OBRA'!C$1&", ","")& IF(INDEX('ETAPA OBRA'!D:D,MATCH($B9,'ETAPA OBRA'!$B:$B,0))="x",'ETAPA OBRA'!D$1&", ","")& IF(INDEX('ETAPA OBRA'!F:F,MATCH($B9,'ETAPA OBRA'!$B:$B,0))="x",'ETAPA OBRA'!F$1&", ","")& IF(INDEX('ETAPA OBRA'!G:G,MATCH($B9,'ETAPA OBRA'!$B:$B,0))="x",'ETAPA OBRA'!G$1&", ","")& IF(INDEX('ETAPA OBRA'!H:H,MATCH($B9,'ETAPA OBRA'!$B:$B,0))="x",'ETAPA OBRA'!H$1&", ","")& IF(INDEX('ETAPA OBRA'!I:I,MATCH($B9,'ETAPA OBRA'!$B:$B,0))="x",'ETAPA OBRA'!I$1&", ","")& IF(INDEX('ETAPA OBRA'!J:J,MATCH($B9,'ETAPA OBRA'!$B:$B,0))="x",'ETAPA OBRA'!J$1&", ","")& IF(INDEX('ETAPA OBRA'!K:K,MATCH($B9,'ETAPA OBRA'!$B:$B,0))="x",'ETAPA OBRA'!K$1&", ","")& IF(INDEX('ETAPA OBRA'!L:L,MATCH($B9,'ETAPA OBRA'!$B:$B,0))="x",'ETAPA OBRA'!L$1&", ","")& IF(INDEX('ETAPA OBRA'!M:M,MATCH($B9,'ETAPA OBRA'!$B:$B,0))="x",'ETAPA OBRA'!M$1&", ","")& IF(INDEX('ETAPA OBRA'!N:N,MATCH($B9,'ETAPA OBRA'!$B:$B,0))="x",'ETAPA OBRA'!N$1&", ","")& IF(INDEX('ETAPA OBRA'!O:O,MATCH($B9,'ETAPA OBRA'!$B:$B,0))="x",'ETAPA OBRA'!O$1&", ","")& IF(INDEX('ETAPA OBRA'!P:P,MATCH($B9,'ETAPA OBRA'!$B:$B,0))="x",'ETAPA OBRA'!P$1&", ","")& IF(INDEX('ETAPA OBRA'!Q:Q,MATCH($B9,'ETAPA OBRA'!$B:$B,0))="x",'ETAPA OBRA'!Q$1&", ","")& IF(INDEX('ETAPA OBRA'!R:R,MATCH($B9,'ETAPA OBRA'!$B:$B,0))="x",'ETAPA OBRA'!R$1&", ","")& IF(INDEX('ETAPA OBRA'!S:S,MATCH($B9,'ETAPA OBRA'!$B:$B,0))="x",'ETAPA OBRA'!S$1&", ","")& IF(INDEX('ETAPA OBRA'!T:T,MATCH($B9,'ETAPA OBRA'!$B:$B,0))="x",'ETAPA OBRA'!T$1&", ","")& IF(INDEX('ETAPA OBRA'!U:U,MATCH($B9,'ETAPA OBRA'!$B:$B,0))="x",'ETAPA OBRA'!U$1&", ","") )-2),"") -> Laudo de verticalidade, Envio RFI | N9: =IF(M9="","Não iniciada", IF(ISNUMBER(FIND("Cancelada",M9)),"Cancelada", IF(ISNUMBER(FIND("Paralisada",M9)),"Paralisada", IF(ISNUMBER(FIND("Finalizado",M9)),"Finalizado", "Em andamento")))) -> Em andamento | O9: 89264 | P9: =SUM($J9:$L9) -> 56443.33 | Q9: =O9-P9 -> 32820.67 | R9: =IF(O9=0,0,Q9/O9) -> 0.36768092 | S9: =IF(R9>=0.2,"✅ OK - Fechar Parceiro","⚠️ Ajustar Custos (<20%)") -> ✅ OK - Fechar Parceiro | T9: =Cronograma[[#This Row],[STATUS]] -> 🕓 EM ANDAMENTO
A10: 38050008 | B10: =IF(A10<>"","contel-"&TEXT(COUNTA($A$2:A10),"00"),"") -> contel-09 | C10: IHS | D10: FORMOSO | E10: MG | F10: https://maps.app.goo.gl/JBh7GfA722cC6J6y7 | G10: 1682 | H10: 12767 | I10: PEDRO | J10: =SUM(EQUIPE!C10,EQUIPE!E10,EQUIPE!G10,EQUIPE!I10,EQUIPE!K10,EQUIPE!M10,EQUIPE!O10) -> 27000 | K10: 20963.08 | L10: 0 | M10: =IFERROR(LEFT( IF(INDEX('ETAPA OBRA'!C:C,MATCH($B10,'ETAPA OBRA'!$B:$B,0))="x",'ETAPA OBRA'!C$1&", ","")& IF(INDEX('ETAPA OBRA'!D:D,MATCH($B10,'ETAPA OBRA'!$B:$B,0))="x",'ETAPA OBRA'!D$1&", ","")& IF(INDEX('ETAPA OBRA'!F:F,MATCH($B10,'ETAPA OBRA'!$B:$B,0))="x",'ETAPA OBRA'!F$1&", ","")& IF(INDEX('ETAPA OBRA'!G:G,MATCH($B10,'ETAPA OBRA'!$B:$B,0))="x",'ETAPA OBRA'!G$1&", ","")& IF(INDEX('ETAPA OBRA'!H:H,MATCH($B10,'ETAPA OBRA'!$B:$B,0))="x",'ETAPA OBRA'!H$1&", ","")& IF(INDEX('ETAPA OBRA'!I:I,MATCH($B10,'ETAPA OBRA'!$B:$B,0))="x",'ETAPA OBRA'!I$1&", ","")& IF(INDEX('ETAPA OBRA'!J:J,MATCH($B10,'ETAPA OBRA'!$B:$B,0))="x",'ETAPA OBRA'!J$1&", ","")& IF(INDEX('ETAPA OBRA'!K:K,MATCH($B10,'ETAPA OBRA'!$B:$B,0))="x",'ETAPA OBRA'!K$1&", ","")& IF(INDEX('ETAPA OBRA'!L:L,MATCH($B10,'ETAPA OBRA'!$B:$B,0))="x",'ETAPA OBRA'!L$1&", ","")& IF(INDEX('ETAPA OBRA'!M:M,MATCH($B10,'ETAPA OBRA'!$B:$B,0))="x",'ETAPA OBRA'!M$1&", ","")& IF(INDEX('ETAPA OBRA'!N:N,MATCH($B10,'ETAPA OBRA'!$B:$B,0))="x",'ETAPA OBRA'!N$1&", ","")& IF(INDEX('ETAPA OBRA'!O:O,MATCH($B10,'ETAPA OBRA'!$B:$B,0))="x",'ETAPA OBRA'!O$1&", ","")& IF(INDEX('ETAPA OBRA'!P:P,MATCH($B10,'ETAPA OBRA'!$B:$B,0))="x",'ETAPA OBRA'!P$1&", ","")& IF(INDEX('ETAPA OBRA'!Q:Q,MATCH($B10,'ETAPA OBRA'!$B:$B,0))="x",'ETAPA OBRA'!Q$1&", ","")& IF(INDEX('ETAPA OBRA'!R:R,MATCH($B10,'ETAPA OBRA'!$B:$B,0))="x",'ETAPA OBRA'!R$1&", ","")& IF(INDEX('ETAPA OBRA'!S:S,MATCH($B10,'ETAPA OBRA'!$B:$B,0))="x",'ETAPA OBRA'!S$1&", ","")& IF(INDEX('ETAPA OBRA'!T:T,MATCH($B10,'ETAPA OBRA'!$B:$B,0))="x",'ETAPA OBRA'!T$1&", ","")& IF(INDEX('ETAPA OBRA'!U:U,MATCH($B10,'ETAPA OBRA'!$B:$B,0))="x",'ETAPA OBRA'!U$1&", ",""),LEN( IF(INDEX('ETAPA OBRA'!C:C,MATCH($B10,'ETAPA OBRA'!$B:$B,0))="x",'ETAPA OBRA'!C$1&", ","")& IF(INDEX('ETAPA OBRA'!D:D,MATCH($B10,'ETAPA OBRA'!$B:$B,0))="x",'ETAPA OBRA'!D$1&", ","")& IF(INDEX('ETAPA OBRA'!F:F,MATCH($B10,'ETAPA OBRA'!$B:$B,0))="x",'ETAPA OBRA'!F$1&", ","")& IF(INDEX('ETAPA OBRA'!G:G,MATCH($B10,'ETAPA OBRA'!$B:$B,0))="x",'ETAPA OBRA'!G$1&", ","")& IF(INDEX('ETAPA OBRA'!H:H,MATCH($B10,'ETAPA OBRA'!$B:$B,0))="x",'ETAPA OBRA'!H$1&", ","")& IF(INDEX('ETAPA OBRA'!I:I,MATCH($B10,'ETAPA OBRA'!$B:$B,0))="x",'ETAPA OBRA'!I$1&", ","")& IF(INDEX('ETAPA OBRA'!J:J,MATCH($B10,'ETAPA OBRA'!$B:$B,0))="x",'ETAPA OBRA'!J$1&", ","")& IF(INDEX('ETAPA OBRA'!K:K,MATCH($B10,'ETAPA OBRA'!$B:$B,0))="x",'ETAPA OBRA'!K$1&", ","")& IF(INDEX('ETAPA OBRA'!L:L,MATCH($B10,'ETAPA OBRA'!$B:$B,0))="x",'ETAPA OBRA'!L$1&", ","")& IF(INDEX('ETAPA OBRA'!M:M,MATCH($B10,'ETAPA OBRA'!$B:$B,0))="x",'ETAPA OBRA'!M$1&", ","")& IF(INDEX('ETAPA OBRA'!N:N,MATCH($B10,'ETAPA OBRA'!$B:$B,0))="x",'ETAPA OBRA'!N$1&", ","")& IF(INDEX('ETAPA OBRA'!O:O,MATCH($B10,'ETAPA OBRA'!$B:$B,0))="x",'ETAPA OBRA'!O$1&", ","")& IF(INDEX('ETAPA OBRA'!P:P,MATCH($B10,'ETAPA OBRA'!$B:$B,0))="x",'ETAPA OBRA'!P$1&", ","")& IF(INDEX('ETAPA OBRA'!Q:Q,MATCH($B10,'ETAPA OBRA'!$B:$B,0))="x",'ETAPA OBRA'!Q$1&", ","")& IF(INDEX('ETAPA OBRA'!R:R,MATCH($B10,'ETAPA OBRA'!$B:$B,0))="x",'ETAPA OBRA'!R$1&", ","")& IF(INDEX('ETAPA OBRA'!S:S,MATCH($B10,'ETAPA OBRA'!$B:$B,0))="x",'ETAPA OBRA'!S$1&", ","")& IF(INDEX('ETAPA OBRA'!T:T,MATCH($B10,'ETAPA OBRA'!$B:$B,0))="x",'ETAPA OBRA'!T$1&", ","")& IF(INDEX('ETAPA OBRA'!U:U,MATCH($B10,'ETAPA OBRA'!$B:$B,0))="x",'ETAPA OBRA'!U$1&", ","") )-2),"") -> Laudo de verticalidade, Envio RFI | N10: =IF(M10="","Não iniciada", IF(ISNUMBER(FIND("Cancelada",M10)),"Cancelada", IF(ISNUMBER(FIND("Paralisada",M10)),"Paralisada", IF(ISNUMBER(FIND("Finalizado",M10)),"Finalizado", "Em andamento")))) -> Em andamento | O10: 89264 | P10: =SUM($J10:$L10) -> 47963.08 | Q10: =O10-P10 -> 41300.92 | R10: =IF(O10=0,0,Q10/O10) -> 0.46268283 | S10: =IF(R10>=0.2,"✅ OK - Fechar Parceiro","⚠️ Ajustar Custos (<20%)") -> ✅ OK - Fechar Parceiro | T10: =Cronograma[[#This Row],[STATUS]] -> ⏰ ATRASADO
A11: 88050062 | B11: =IF(A11<>"","contel-"&TEXT(COUNTA($A$2:A11),"00"),"") -> contel-10 | C11: IHS | D11: QUIXADÁ | E11: CE | F11: https://maps.app.goo.gl/QdG7puZ7e7jJzaxS9 | G11: 1683 | H11: 12768 | I11: PEDRO | J11: =SUM(EQUIPE!C11,EQUIPE!E11,EQUIPE!G11,EQUIPE!I11,EQUIPE!K11,EQUIPE!M11,EQUIPE!O11) -> 24500 | K11: 18952.57 | L11: 0 | M11: =IFERROR(LEFT( IF(INDEX('ETAPA OBRA'!C:C,MATCH($B11,'ETAPA OBRA'!$B:$B,0))="x",'ETAPA OBRA'!C$1&", ","")& IF(INDEX('ETAPA OBRA'!D:D,MATCH($B11,'ETAPA OBRA'!$B:$B,0))="x",'ETAPA OBRA'!D$1&", ","")& IF(INDEX('ETAPA OBRA'!F:F,MATCH($B11,'ETAPA OBRA'!$B:$B,0))="x",'ETAPA OBRA'!F$1&", ","")& IF(INDEX('ETAPA OBRA'!G:G,MATCH($B11,'ETAPA OBRA'!$B:$B,0))="x",'ETAPA OBRA'!G$1&", ","")& IF(INDEX('ETAPA OBRA'!H:H,MATCH($B11,'ETAPA OBRA'!$B:$B,0))="x",'ETAPA OBRA'!H$1&", ","")& IF(INDEX('ETAPA OBRA'!I:I,MATCH($B11,'ETAPA OBRA'!$B:$B,0))="x",'ETAPA OBRA'!I$1&", ","")& IF(INDEX('ETAPA OBRA'!J:J,MATCH($B11,'ETAPA OBRA'!$B:$B,0))="x",'ETAPA OBRA'!J$1&", ","")& IF(INDEX('ETAPA OBRA'!K:K,MATCH($B11,'ETAPA OBRA'!$B:$B,0))="x",'ETAPA OBRA'!K$1&", ","")& IF(INDEX('ETAPA OBRA'!L:L,MATCH($B11,'ETAPA OBRA'!$B:$B,0))="x",'ETAPA OBRA'!L$1&", ","")& IF(INDEX('ETAPA OBRA'!M:M,MATCH($B11,'ETAPA OBRA'!$B:$B,0))="x",'ETAPA OBRA'!M$1&", ","")& IF(INDEX('ETAPA OBRA'!N:N,MATCH($B11,'ETAPA OBRA'!$B:$B,0))="x",'ETAPA OBRA'!N$1&", ","")& IF(INDEX('ETAPA OBRA'!O:O,MATCH($B11,'ETAPA OBRA'!$B:$B,0))="x",'ETAPA OBRA'!O$1&", ","")& IF(INDEX('ETAPA OBRA'!P:P,MATCH($B11,'ETAPA OBRA'!$B:$B,0))="x",'ETAPA OBRA'!P$1&", ","")& IF(INDEX('ETAPA OBRA'!Q:Q,MATCH($B11,'ETAPA OBRA'!$B:$B,0))="x",'ETAPA OBRA'!Q$1&", ","")& IF(INDEX('ETAPA OBRA'!R:R,MATCH($B11,'ETAPA OBRA'!$B:$B,0))="x",'ETAPA OBRA'!R$1&", ","")& IF(INDEX('ETAPA OBRA'!S:S,MATCH($B11,'ETAPA OBRA'!$B:$B,0))="x",'ETAPA OBRA'!S$1&", ","")& IF(INDEX('ETAPA OBRA'!T:T,MATCH($B11,'ETAPA OBRA'!$B:$B,0))="x",'ETAPA OBRA'!T$1&", ","")& IF(INDEX('ETAPA OBRA'!U:U,MATCH($B11,'ETAPA OBRA'!$B:$B,0))="x",'ETAPA OBRA'!U$1&", ",""),LEN( IF(INDEX('ETAPA OBRA'!C:C,MATCH($B11,'ETAPA OBRA'!$B:$B,0))="x",'ETAPA OBRA'!C$1&", ","")& IF(INDEX('ETAPA OBRA'!D:D,MATCH($B11,'ETAPA OBRA'!$B:$B,0))="x",'ETAPA OBRA'!D$1&", ","")& IF(INDEX('ETAPA OBRA'!F:F,MATCH($B11,'ETAPA OBRA'!$B:$B,0))="x",'ETAPA OBRA'!F$1&", ","")& IF(INDEX('ETAPA OBRA'!G:G,MATCH($B11,'ETAPA OBRA'!$B:$B,0))="x",'ETAPA OBRA'!G$1&", ","")& IF(INDEX('ETAPA OBRA'!H:H,MATCH($B11,'ETAPA OBRA'!$B:$B,0))="x",'ETAPA OBRA'!H$1&", ","")& IF(INDEX('ETAPA OBRA'!I:I,MATCH($B11,'ETAPA OBRA'!$B:$B,0))="x",'ETAPA OBRA'!I$1&", ","")& IF(INDEX('ETAPA OBRA'!J:J,MATCH($B11,'ETAPA OBRA'!$B:$B,0))="x",'ETAPA OBRA'!J$1&", ","")& IF(INDEX('ETAPA OBRA'!K:K,MATCH($B11,'ETAPA OBRA'!$B:$B,0))="x",'ETAPA OBRA'!K$1&", ","")& IF(INDEX('ETAPA OBRA'!L:L,MATCH($B11,'ETAPA OBRA'!$B:$B,0))="x",'ETAPA OBRA'!L$1&", ","")& IF(INDEX('ETAPA OBRA'!M:M,MATCH($B11,'ETAPA OBRA'!$B:$B,0))="x",'ETAPA OBRA'!M$1&", ","")& IF(INDEX('ETAPA OBRA'!N:N,MATCH($B11,'ETAPA OBRA'!$B:$B,0))="x",'ETAPA OBRA'!N$1&", ","")& IF(INDEX('ETAPA OBRA'!O:O,MATCH($B11,'ETAPA OBRA'!$B:$B,0))="x",'ETAPA OBRA'!O$1&", ","")& IF(INDEX('ETAPA OBRA'!P:P,MATCH($B11,'ETAPA OBRA'!$B:$B,0))="x",'ETAPA OBRA'!P$1&", ","")& IF(INDEX('ETAPA OBRA'!Q:Q,MATCH($B11,'ETAPA OBRA'!$B:$B,0))="x",'ETAPA OBRA'!Q$1&", ","")& IF(INDEX('ETAPA OBRA'!R:R,MATCH($B11,'ETAPA OBRA'!$B:$B,0))="x",'ETAPA OBRA'!R$1&", ","")& IF(INDEX('ETAPA OBRA'!S:S,MATCH($B11,'ETAPA OBRA'!$B:$B,0))="x",'ETAPA OBRA'!S$1&", ","")& IF(INDEX('ETAPA OBRA'!T:T,MATCH($B11,'ETAPA OBRA'!$B:$B,0))="x",'ETAPA OBRA'!T$1&", ","")& IF(INDEX('ETAPA OBRA'!U:U,MATCH($B11,'ETAPA OBRA'!$B:$B,0))="x",'ETAPA OBRA'!U$1&", ","") )-2),"") -> Finalizado | N11: =IF(M11="","Não iniciada", IF(ISNUMBER(FIND("Cancelada",M11)),"Cancelada", IF(ISNUMBER(FIND("Paralisada",M11)),"Paralisada", IF(ISNUMBER(FIND("Finalizado",M11)),"Finalizado", "Em andamento")))) -> Finalizado | O11: 89264 | P11: =SUM($J11:$L11) -> 43452.57 | Q11: =O11-P11 -> 45811.43 | R11: =IF(O11=0,0,Q11/O11) -> 0.51321283 | S11: =IF(R11>=0.2,"✅ OK - Fechar Parceiro","⚠️ Ajustar Custos (<20%)") -> ✅ OK - Fechar Parceiro | T11: =Cronograma[[#This Row],[STATUS]] -> ✅ CONCLUÍDO
A12: 88050069 | B12: =IF(A12<>"","contel-"&TEXT(COUNTA($A$2:A12),"00"),"") -> contel-11 | C12: IHS | D12: MALHADA | E12: CE | F12: https://maps.app.goo.gl/7anpJtZhoq92gEPg7 | G12: 1684 | H12: 12769 | I12: PEDRO | J12: =SUM(EQUIPE!C12,EQUIPE!E12,EQUIPE!G12,EQUIPE!I12,EQUIPE!K12,EQUIPE!M12,EQUIPE!O12) -> 0 | K12: 13872.51 | L12: 0 | M12: =IFERROR(LEFT( IF(INDEX('ETAPA OBRA'!C:C,MATCH($B12,'ETAPA OBRA'!$B:$B,0))="x",'ETAPA OBRA'!C$1&", ","")& IF(INDEX('ETAPA OBRA'!D:D,MATCH($B12,'ETAPA OBRA'!$B:$B,0))="x",'ETAPA OBRA'!D$1&", ","")& IF(INDEX('ETAPA OBRA'!F:F,MATCH($B12,'ETAPA OBRA'!$B:$B,0))="x",'ETAPA OBRA'!F$1&", ","")& IF(INDEX('ETAPA OBRA'!G:G,MATCH($B12,'ETAPA OBRA'!$B:$B,0))="x",'ETAPA OBRA'!G$1&", ","")& IF(INDEX('ETAPA OBRA'!H:H,MATCH($B12,'ETAPA OBRA'!$B:$B,0))="x",'ETAPA OBRA'!H$1&", ","")& IF(INDEX('ETAPA OBRA'!I:I,MATCH($B12,'ETAPA OBRA'!$B:$B,0))="x",'ETAPA OBRA'!I$1&", ","")& IF(INDEX('ETAPA OBRA'!J:J,MATCH($B12,'ETAPA OBRA'!$B:$B,0))="x",'ETAPA OBRA'!J$1&", ","")& IF(INDEX('ETAPA OBRA'!K:K,MATCH($B12,'ETAPA OBRA'!$B:$B,0))="x",'ETAPA OBRA'!K$1&", ","")& IF(INDEX('ETAPA OBRA'!L:L,MATCH($B12,'ETAPA OBRA'!$B:$B,0))="x",'ETAPA OBRA'!L$1&", ","")& IF(INDEX('ETAPA OBRA'!M:M,MATCH($B12,'ETAPA OBRA'!$B:$B,0))="x",'ETAPA OBRA'!M$1&", ","")& IF(INDEX('ETAPA OBRA'!N:N,MATCH($B12,'ETAPA OBRA'!$B:$B,0))="x",'ETAPA OBRA'!N$1&", ","")& IF(INDEX('ETAPA OBRA'!O:O,MATCH($B12,'ETAPA OBRA'!$B:$B,0))="x",'ETAPA OBRA'!O$1&", ","")& IF(INDEX('ETAPA OBRA'!P:P,MATCH($B12,'ETAPA OBRA'!$B:$B,0))="x",'ETAPA OBRA'!P$1&", ","")& IF(INDEX('ETAPA OBRA'!Q:Q,MATCH($B12,'ETAPA OBRA'!$B:$B,0))="x",'ETAPA OBRA'!Q$1&", ","")& IF(INDEX('ETAPA OBRA'!R:R,MATCH($B12,'ETAPA OBRA'!$B:$B,0))="x",'ETAPA OBRA'!R$1&", ","")& IF(INDEX('ETAPA OBRA'!S:S,MATCH($B12,'ETAPA OBRA'!$B:$B,0))="x",'ETAPA OBRA'!S$1&", ","")& IF(INDEX('ETAPA OBRA'!T:T,MATCH($B12,'ETAPA OBRA'!$B:$B,0))="x",'ETAPA OBRA'!T$1&", ","")& IF(INDEX('ETAPA OBRA'!U:U,MATCH($B12,'ETAPA OBRA'!$B:$B,0))="x",'ETAPA OBRA'!U$1&", ",""),LEN( IF(INDEX('ETAPA OBRA'!C:C,MATCH($B12,'ETAPA OBRA'!$B:$B,0))="x",'ETAPA OBRA'!C$1&", ","")& IF(INDEX('ETAPA OBRA'!D:D,MATCH($B12,'ETAPA OBRA'!$B:$B,0))="x",'ETAPA OBRA'!D$1&", ","")& IF(INDEX('ETAPA OBRA'!F:F,MATCH($B12,'ETAPA OBRA'!$B:$B,0))="x",'ETAPA OBRA'!F$1&", ","")& IF(INDEX('ETAPA OBRA'!G:G,MATCH($B12,'ETAPA OBRA'!$B:$B,0))="x",'ETAPA OBRA'!G$1&", ","")& IF(INDEX('ETAPA OBRA'!H:H,MATCH($B12,'ETAPA OBRA'!$B:$B,0))="x",'ETAPA OBRA'!H$1&", ","")& IF(INDEX('ETAPA OBRA'!I:I,MATCH($B12,'ETAPA OBRA'!$B:$B,0))="x",'ETAPA OBRA'!I$1&", ","")& IF(INDEX('ETAPA OBRA'!J:J,MATCH($B12,'ETAPA OBRA'!$B:$B,0))="x",'ETAPA OBRA'!J$1&", ","")& IF(INDEX('ETAPA OBRA'!K:K,MATCH($B12,'ETAPA OBRA'!$B:$B,0))="x",'ETAPA OBRA'!K$1&", ","")& IF(INDEX('ETAPA OBRA'!L:L,MATCH($B12,'ETAPA OBRA'!$B:$B,0))="x",'ETAPA OBRA'!L$1&", ","")& IF(INDEX('ETAPA OBRA'!M:M,MATCH($B12,'ETAPA OBRA'!$B:$B,0))="x",'ETAPA OBRA'!M$1&", ","")& IF(INDEX('ETAPA OBRA'!N:N,MATCH($B12,'ETAPA OBRA'!$B:$B,0))="x",'ETAPA OBRA'!N$1&", ","")& IF(INDEX('ETAPA OBRA'!O:O,MATCH($B12,'ETAPA OBRA'!$B:$B,0))="x",'ETAPA OBRA'!O$1&", ","")& IF(INDEX('ETAPA OBRA'!P:P,MATCH($B12,'ETAPA OBRA'!$B:$B,0))="x",'ETAPA OBRA'!P$1&", ","")& IF(INDEX('ETAPA OBRA'!Q:Q,MATCH($B12,'ETAPA OBRA'!$B:$B,0))="x",'ETAPA OBRA'!Q$1&", ","")& IF(INDEX('ETAPA OBRA'!R:R,MATCH($B12,'ETAPA OBRA'!$B:$B,0))="x",'ETAPA OBRA'!R$1&", ","")& IF(INDEX('ETAPA OBRA'!S:S,MATCH($B12,'ETAPA OBRA'!$B:$B,0))="x",'ETAPA OBRA'!S$1&", ","")& IF(INDEX('ETAPA OBRA'!T:T,MATCH($B12,'ETAPA OBRA'!$B:$B,0))="x",'ETAPA OBRA'!T$1&", ","")& IF(INDEX('ETAPA OBRA'!U:U,MATCH($B12,'ETAPA OBRA'!$B:$B,0))="x",'ETAPA OBRA'!U$1&", ","") )-2),"") -> Finalizado | N12: =IF(M12="","Não iniciada", IF(ISNUMBER(FIND("Cancelada",M12)),"Cancelada", IF(ISNUMBER(FIND("Paralisada",M12)),"Paralisada", IF(ISNUMBER(FIND("Finalizado",M12)),"Finalizado", "Em andamento")))) -> Finalizado | O12: 89264 | P12: =SUM($J12:$L12) -> 13872.51 | Q12: =O12-P12 -> 75391.49 | R12: =IF(O12=0,0,Q12/O12) -> 0.84459009 | S12: =IF(R12>=0.2,"✅ OK - Fechar Parceiro","⚠️ Ajustar Custos (<20%)") -> ✅ OK - Fechar Parceiro | T12: =Cronograma[[#This Row],[STATUS]] -> ✅ CONCLUÍDO
A13: 83010085 | B13: =IF(A13<>"","contel-"&TEXT(COUNTA($A$2:A13),"00"),"") -> contel-12 | C13: IHS | D13: BERNARDINO BATISTA | E13: PB | F13: https://maps.app.goo.gl/rkUwhhpPfBuKEvyx7 | G13: 1685 | H13: 12770 | I13: PEDRO | J13: =SUM(EQUIPE!C13,EQUIPE!E13,EQUIPE!G13,EQUIPE!I13,EQUIPE!K13,EQUIPE!M13,EQUIPE!O13) -> 0 | K13: 25453.15 | L13: 0 | M13: =IFERROR(LEFT( IF(INDEX('ETAPA OBRA'!C:C,MATCH($B13,'ETAPA OBRA'!$B:$B,0))="x",'ETAPA OBRA'!C$1&", ","")& IF(INDEX('ETAPA OBRA'!D:D,MATCH($B13,'ETAPA OBRA'!$B:$B,0))="x",'ETAPA OBRA'!D$1&", ","")& IF(INDEX('ETAPA OBRA'!F:F,MATCH($B13,'ETAPA OBRA'!$B:$B,0))="x",'ETAPA OBRA'!F$1&", ","")& IF(INDEX('ETAPA OBRA'!G:G,MATCH($B13,'ETAPA OBRA'!$B:$B,0))="x",'ETAPA OBRA'!G$1&", ","")& IF(INDEX('ETAPA OBRA'!H:H,MATCH($B13,'ETAPA OBRA'!$B:$B,0))="x",'ETAPA OBRA'!H$1&", ","")& IF(INDEX('ETAPA OBRA'!I:I,MATCH($B13,'ETAPA OBRA'!$B:$B,0))="x",'ETAPA OBRA'!I$1&", ","")& IF(INDEX('ETAPA OBRA'!J:J,MATCH($B13,'ETAPA OBRA'!$B:$B,0))="x",'ETAPA OBRA'!J$1&", ","")& IF(INDEX('ETAPA OBRA'!K:K,MATCH($B13,'ETAPA OBRA'!$B:$B,0))="x",'ETAPA OBRA'!K$1&", ","")& IF(INDEX('ETAPA OBRA'!L:L,MATCH($B13,'ETAPA OBRA'!$B:$B,0))="x",'ETAPA OBRA'!L$1&", ","")& IF(INDEX('ETAPA OBRA'!M:M,MATCH($B13,'ETAPA OBRA'!$B:$B,0))="x",'ETAPA OBRA'!M$1&", ","")& IF(INDEX('ETAPA OBRA'!N:N,MATCH($B13,'ETAPA OBRA'!$B:$B,0))="x",'ETAPA OBRA'!N$1&", ","")& IF(INDEX('ETAPA OBRA'!O:O,MATCH($B13,'ETAPA OBRA'!$B:$B,0))="x",'ETAPA OBRA'!O$1&", ","")& IF(INDEX('ETAPA OBRA'!P:P,MATCH($B13,'ETAPA OBRA'!$B:$B,0))="x",'ETAPA OBRA'!P$1&", ","")& IF(INDEX('ETAPA OBRA'!Q:Q,MATCH($B13,'ETAPA OBRA'!$B:$B,0))="x",'ETAPA OBRA'!Q$1&", ","")& IF(INDEX('ETAPA OBRA'!R:R,MATCH($B13,'ETAPA OBRA'!$B:$B,0))="x",'ETAPA OBRA'!R$1&", ","")& IF(INDEX('ETAPA OBRA'!S:S,MATCH($B13,'ETAPA OBRA'!$B:$B,0))="x",'ETAPA OBRA'!S$1&", ","")& IF(INDEX('ETAPA OBRA'!T:T,MATCH($B13,'ETAPA OBRA'!$B:$B,0))="x",'ETAPA OBRA'!T$1&", ","")& IF(INDEX('ETAPA OBRA'!U:U,MATCH($B13,'ETAPA OBRA'!$B:$B,0))="x",'ETAPA OBRA'!U$1&", ",""),LEN( IF(INDEX('ETAPA OBRA'!C:C,MATCH($B13,'ETAPA OBRA'!$B:$B,0))="x",'ETAPA OBRA'!C$1&", ","")& IF(INDEX('ETAPA OBRA'!D:D,MATCH($B13,'ETAPA OBRA'!$B:$B,0))="x",'ETAPA OBRA'!D$1&", ","")& IF(INDEX('ETAPA OBRA'!F:F,MATCH($B13,'ETAPA OBRA'!$B:$B,0))="x",'ETAPA OBRA'!F$1&", ","")& IF(INDEX('ETAPA OBRA'!G:G,MATCH($B13,'ETAPA OBRA'!$B:$B,0))="x",'ETAPA OBRA'!G$1&", ","")& IF(INDEX('ETAPA OBRA'!H:H,MATCH($B13,'ETAPA OBRA'!$B:$B,0))="x",'ETAPA OBRA'!H$1&", ","")& IF(INDEX('ETAPA OBRA'!I:I,MATCH($B13,'ETAPA OBRA'!$B:$B,0))="x",'ETAPA OBRA'!I$1&", ","")& IF(INDEX('ETAPA OBRA'!J:J,MATCH($B13,'ETAPA OBRA'!$B:$B,0))="x",'ETAPA OBRA'!J$1&", ","")& IF(INDEX('ETAPA OBRA'!K:K,MATCH($B13,'ETAPA OBRA'!$B:$B,0))="x",'ETAPA OBRA'!K$1&", ","")& IF(INDEX('ETAPA OBRA'!L:L,MATCH($B13,'ETAPA OBRA'!$B:$B,0))="x",'ETAPA OBRA'!L$1&", ","")& IF(INDEX('ETAPA OBRA'!M:M,MATCH($B13,'ETAPA OBRA'!$B:$B,0))="x",'ETAPA OBRA'!M$1&", ","")& IF(INDEX('ETAPA OBRA'!N:N,MATCH($B13,'ETAPA OBRA'!$B:$B,0))="x",'ETAPA OBRA'!N$1&", ","")& IF(INDEX('ETAPA OBRA'!O:O,MATCH($B13,'ETAPA OBRA'!$B:$B,0))="x",'ETAPA OBRA'!O$1&", ","")& IF(INDEX('ETAPA OBRA'!P:P,MATCH($B13,'ETAPA OBRA'!$B:$B,0))="x",'ETAPA OBRA'!P$1&", ","")& IF(INDEX('ETAPA OBRA'!Q:Q,MATCH($B13,'ETAPA OBRA'!$B:$B,0))="x",'ETAPA OBRA'!Q$1&", ","")& IF(INDEX('ETAPA OBRA'!R:R,MATCH($B13,'ETAPA OBRA'!$B:$B,0))="x",'ETAPA OBRA'!R$1&", ","")& IF(INDEX('ETAPA OBRA'!S:S,MATCH($B13,'ETAPA OBRA'!$B:$B,0))="x",'ETAPA OBRA'!S$1&", ","")& IF(INDEX('ETAPA OBRA'!T:T,MATCH($B13,'ETAPA OBRA'!$B:$B,0))="x",'ETAPA OBRA'!T$1&", ","")& IF(INDEX('ETAPA OBRA'!U:U,MATCH($B13,'ETAPA OBRA'!$B:$B,0))="x",'ETAPA OBRA'!U$1&", ","") )-2),"") -> Fabricação / Galvanização | N13: =IF(M13="","Não iniciada", IF(ISNUMBER(FIND("Cancelada",M13)),"Cancelada", IF(ISNUMBER(FIND("Paralisada",M13)),"Paralisada", IF(ISNUMBER(FIND("Finalizado",M13)),"Finalizado", "Em andamento")))) -> Em andamento | O13: 89264 | P13: =SUM($J13:$L13) -> 25453.15 | Q13: =O13-P13 -> 63810.85 | R13: =IF(O13=0,0,Q13/O13) -> 0.71485537 | S13: =IF(R13>=0.2,"✅ OK - Fechar Parceiro","⚠️ Ajustar Custos (<20%)") -> ✅ OK - Fechar Parceiro | T13: =Cronograma[[#This Row],[STATUS]] -> ⏰ ATRASADO
A14: 89050013 | B14: =IF(A14<>"","contel-"&TEXT(COUNTA($A$2:A14),"00"),"") -> contel-13 | C14: IHS | D14: LAGOA DO SITIO | E14: PI | F14: https://maps.app.goo.gl/1h4ggSVzz3kafxQu8 | G14: 1686 | H14: 12771 | I14: PEDRO | J14: =SUM(EQUIPE!C14,EQUIPE!E14,EQUIPE!G14,EQUIPE!I14,EQUIPE!K14,EQUIPE!M14,EQUIPE!O14) -> 0 | K14: 20703.67 | L14: 0 | M14: =IFERROR(LEFT( IF(INDEX('ETAPA OBRA'!C:C,MATCH($B14,'ETAPA OBRA'!$B:$B,0))="x",'ETAPA OBRA'!C$1&", ","")& IF(INDEX('ETAPA OBRA'!D:D,MATCH($B14,'ETAPA OBRA'!$B:$B,0))="x",'ETAPA OBRA'!D$1&", ","")& IF(INDEX('ETAPA OBRA'!F:F,MATCH($B14,'ETAPA OBRA'!$B:$B,0))="x",'ETAPA OBRA'!F$1&", ","")& IF(INDEX('ETAPA OBRA'!G:G,MATCH($B14,'ETAPA OBRA'!$B:$B,0))="x",'ETAPA OBRA'!G$1&", ","")& IF(INDEX('ETAPA OBRA'!H:H,MATCH($B14,'ETAPA OBRA'!$B:$B,0))="x",'ETAPA OBRA'!H$1&", ","")& IF(INDEX('ETAPA OBRA'!I:I,MATCH($B14,'ETAPA OBRA'!$B:$B,0))="x",'ETAPA OBRA'!I$1&", ","")& IF(INDEX('ETAPA OBRA'!J:J,MATCH($B14,'ETAPA OBRA'!$B:$B,0))="x",'ETAPA OBRA'!J$1&", ","")& IF(INDEX('ETAPA OBRA'!K:K,MATCH($B14,'ETAPA OBRA'!$B:$B,0))="x",'ETAPA OBRA'!K$1&", ","")& IF(INDEX('ETAPA OBRA'!L:L,MATCH($B14,'ETAPA OBRA'!$B:$B,0))="x",'ETAPA OBRA'!L$1&", ","")& IF(INDEX('ETAPA OBRA'!M:M,MATCH($B14,'ETAPA OBRA'!$B:$B,0))="x",'ETAPA OBRA'!M$1&", ","")& IF(INDEX('ETAPA OBRA'!N:N,MATCH($B14,'ETAPA OBRA'!$B:$B,0))="x",'ETAPA OBRA'!N$1&", ","")& IF(INDEX('ETAPA OBRA'!O:O,MATCH($B14,'ETAPA OBRA'!$B:$B,0))="x",'ETAPA OBRA'!O$1&", ","")& IF(INDEX('ETAPA OBRA'!P:P,MATCH($B14,'ETAPA OBRA'!$B:$B,0))="x",'ETAPA OBRA'!P$1&", ","")& IF(INDEX('ETAPA OBRA'!Q:Q,MATCH($B14,'ETAPA OBRA'!$B:$B,0))="x",'ETAPA OBRA'!Q$1&", ","")& IF(INDEX('ETAPA OBRA'!R:R,MATCH($B14,'ETAPA OBRA'!$B:$B,0))="x",'ETAPA OBRA'!R$1&", ","")& IF(INDEX('ETAPA OBRA'!S:S,MATCH($B14,'ETAPA OBRA'!$B:$B,0))="x",'ETAPA OBRA'!S$1&", ","")& IF(INDEX('ETAPA OBRA'!T:T,MATCH($B14,'ETAPA OBRA'!$B:$B,0))="x",'ETAPA OBRA'!T$1&", ","")& IF(INDEX('ETAPA OBRA'!U:U,MATCH($B14,'ETAPA OBRA'!$B:$B,0))="x",'ETAPA OBRA'!U$1&", ",""),LEN( IF(INDEX('ETAPA OBRA'!C:C,MATCH($B14,'ETAPA OBRA'!$B:$B,0))="x",'ETAPA OBRA'!C$1&", ","")& IF(INDEX('ETAPA OBRA'!D:D,MATCH($B14,'ETAPA OBRA'!$B:$B,0))="x",'ETAPA OBRA'!D$1&", ","")& IF(INDEX('ETAPA OBRA'!F:F,MATCH($B14,'ETAPA OBRA'!$B:$B,0))="x",'ETAPA OBRA'!F$1&", ","")& IF(INDEX('ETAPA OBRA'!G:G,MATCH($B14,'ETAPA OBRA'!$B:$B,0))="x",'ETAPA OBRA'!G$1&", ","")& IF(INDEX('ETAPA OBRA'!H:H,MATCH($B14,'ETAPA OBRA'!$B:$B,0))="x",'ETAPA OBRA'!H$1&", ","")& IF(INDEX('ETAPA OBRA'!I:I,MATCH($B14,'ETAPA OBRA'!$B:$B,0))="x",'ETAPA OBRA'!I$1&", ","")& IF(INDEX('ETAPA OBRA'!J:J,MATCH($B14,'ETAPA OBRA'!$B:$B,0))="x",'ETAPA OBRA'!J$1&", ","")& IF(INDEX('ETAPA OBRA'!K:K,MATCH($B14,'ETAPA OBRA'!$B:$B,0))="x",'ETAPA OBRA'!K$1&", ","")& IF(INDEX('ETAPA OBRA'!L:L,MATCH($B14,'ETAPA OBRA'!$B:$B,0))="x",'ETAPA OBRA'!L$1&", ","")& IF(INDEX('ETAPA OBRA'!M:M,MATCH($B14,'ETAPA OBRA'!$B:$B,0))="x",'ETAPA OBRA'!M$1&", ","")& IF(INDEX('ETAPA OBRA'!N:N,MATCH($B14,'ETAPA OBRA'!$B:$B,0))="x",'ETAPA OBRA'!N$1&", ","")& IF(INDEX('ETAPA OBRA'!O:O,MATCH($B14,'ETAPA OBRA'!$B:$B,0))="x",'ETAPA OBRA'!O$1&", ","")& IF(INDEX('ETAPA OBRA'!P:P,MATCH($B14,'ETAPA OBRA'!$B:$B,0))="x",'ETAPA OBRA'!P$1&", ","")& IF(INDEX('ETAPA OBRA'!Q:Q,MATCH($B14,'ETAPA OBRA'!$B:$B,0))="x",'ETAPA OBRA'!Q$1&", ","")& IF(INDEX('ETAPA OBRA'!R:R,MATCH($B14,'ETAPA OBRA'!$B:$B,0))="x",'ETAPA OBRA'!R$1&", ","")& IF(INDEX('ETAPA OBRA'!S:S,MATCH($B14,'ETAPA OBRA'!$B:$B,0))="x",'ETAPA OBRA'!S$1&", ","")& IF(INDEX('ETAPA OBRA'!T:T,MATCH($B14,'ETAPA OBRA'!$B:$B,0))="x",'ETAPA OBRA'!T$1&", ","")& IF(INDEX('ETAPA OBRA'!U:U,MATCH($B14,'ETAPA OBRA'!$B:$B,0))="x",'ETAPA OBRA'!U$1&", ","") )-2),"") -> Fabricação / Galvanização | N14: =IF(M14="","Não iniciada", IF(ISNUMBER(FIND("Cancelada",M14)),"Cancelada", IF(ISNUMBER(FIND("Paralisada",M14)),"Paralisada", IF(ISNUMBER(FIND("Finalizado",M14)),"Finalizado", "Em andamento")))) -> Em andamento | O14: 89264 | P14: =SUM($J14:$L14) -> 20703.67 | Q14: =O14-P14 -> 68560.33 | R14: =IF(O14=0,0,Q14/O14) -> 0.76806249 | S14: =IF(R14>=0.2,"✅ OK - Fechar Parceiro","⚠️ Ajustar Custos (<20%)") -> ✅ OK - Fechar Parceiro | T14: =Cronograma[[#This Row],[STATUS]] -> 🕓 EM ANDAMENTO
A15: BR55017-A | B15: =IF(A15<>"","contel-"&TEXT(COUNTA($A$2:A15),"00"),"") -> contel-14 | C15: SBA | D15: MARQUES DE SOUSA | E15: RS | F15: https://maps.app.goo.gl/NXVPhzLsuvYKgB5N9 | G15: 1688 | H15: 12707 | I15: DANILO | J15: =SUM(EQUIPE!C15,EQUIPE!E15,EQUIPE!G15,EQUIPE!I15,EQUIPE!K15,EQUIPE!M15,EQUIPE!O15) -> 7800 | K15: 0 | L15: 4071.47 | M15: =IFERROR(LEFT( IF(INDEX('ETAPA OBRA'!C:C,MATCH($B15,'ETAPA OBRA'!$B:$B,0))="x",'ETAPA OBRA'!C$1&", ","")& IF(INDEX('ETAPA OBRA'!D:D,MATCH($B15,'ETAPA OBRA'!$B:$B,0))="x",'ETAPA OBRA'!D$1&", ","")& IF(INDEX('ETAPA OBRA'!F:F,MATCH($B15,'ETAPA OBRA'!$B:$B,0))="x",'ETAPA OBRA'!F$1&", ","")& IF(INDEX('ETAPA OBRA'!G:G,MATCH($B15,'ETAPA OBRA'!$B:$B,0))="x",'ETAPA OBRA'!G$1&", ","")& IF(INDEX('ETAPA OBRA'!H:H,MATCH($B15,'ETAPA OBRA'!$B:$B,0))="x",'ETAPA OBRA'!H$1&", ","")& IF(INDEX('ETAPA OBRA'!I:I,MATCH($B15,'ETAPA OBRA'!$B:$B,0))="x",'ETAPA OBRA'!I$1&", ","")& IF(INDEX('ETAPA OBRA'!J:J,MATCH($B15,'ETAPA OBRA'!$B:$B,0))="x",'ETAPA OBRA'!J$1&", ","")& IF(INDEX('ETAPA OBRA'!K:K,MATCH($B15,'ETAPA OBRA'!$B:$B,0))="x",'ETAPA OBRA'!K$1&", ","")& IF(INDEX('ETAPA OBRA'!L:L,MATCH($B15,'ETAPA OBRA'!$B:$B,0))="x",'ETAPA OBRA'!L$1&", ","")& IF(INDEX('ETAPA OBRA'!M:M,MATCH($B15,'ETAPA OBRA'!$B:$B,0))="x",'ETAPA OBRA'!M$1&", ","")& IF(INDEX('ETAPA OBRA'!N:N,MATCH($B15,'ETAPA OBRA'!$B:$B,0))="x",'ETAPA OBRA'!N$1&", ","")& IF(INDEX('ETAPA OBRA'!O:O,MATCH($B15,'ETAPA OBRA'!$B:$B,0))="x",'ETAPA OBRA'!O$1&", ","")& IF(INDEX('ETAPA OBRA'!P:P,MATCH($B15,'ETAPA OBRA'!$B:$B,0))="x",'ETAPA OBRA'!P$1&", ","")& IF(INDEX('ETAPA OBRA'!Q:Q,MATCH($B15,'ETAPA OBRA'!$B:$B,0))="x",'ETAPA OBRA'!Q$1&", ","")& IF(INDEX('ETAPA OBRA'!R:R,MATCH($B15,'ETAPA OBRA'!$B:$B,0))="x",'ETAPA OBRA'!R$1&", ","")& IF(INDEX('ETAPA OBRA'!S:S,MATCH($B15,'ETAPA OBRA'!$B:$B,0))="x",'ETAPA OBRA'!S$1&", ","")& IF(INDEX('ETAPA OBRA'!T:T,MATCH($B15,'ETAPA OBRA'!$B:$B,0))="x",'ETAPA OBRA'!T$1&", ","")& IF(INDEX('ETAPA OBRA'!U:U,MATCH($B15,'ETAPA OBRA'!$B:$B,0))="x",'ETAPA OBRA'!U$1&", ",""),LEN( IF(INDEX('ETAPA OBRA'!C:C,MATCH($B15,'ETAPA OBRA'!$B:$B,0))="x",'ETAPA OBRA'!C$1&", ","")& IF(INDEX('ETAPA OBRA'!D:D,MATCH($B15,'ETAPA OBRA'!$B:$B,0))="x",'ETAPA OBRA'!D$1&", ","")& IF(INDEX('ETAPA OBRA'!F:F,MATCH($B15,'ETAPA OBRA'!$B:$B,0))="x",'ETAPA OBRA'!F$1&", ","")& IF(INDEX('ETAPA OBRA'!G:G,MATCH($B15,'ETAPA OBRA'!$B:$B,0))="x",'ETAPA OBRA'!G$1&", ","")& IF(INDEX('ETAPA OBRA'!H:H,MATCH($B15,'ETAPA OBRA'!$B:$B,0))="x",'ETAPA OBRA'!H$1&", ","")& IF(INDEX('ETAPA OBRA'!I:I,MATCH($B15,'ETAPA OBRA'!$B:$B,0))="x",'ETAPA OBRA'!I$1&", ","")& IF(INDEX('ETAPA OBRA'!J:J,MATCH($B15,'ETAPA OBRA'!$B:$B,0))="x",'ETAPA OBRA'!J$1&", ","")& IF(INDEX('ETAPA OBRA'!K:K,MATCH($B15,'ETAPA OBRA'!$B:$B,0))="x",'ETAPA OBRA'!K$1&", ","")& IF(INDEX('ETAPA OBRA'!L:L,MATCH($B15,'ETAPA OBRA'!$B:$B,0))="x",'ETAPA OBRA'!L$1&", ","")& IF(INDEX('ETAPA OBRA'!M:M,MATCH($B15,'ETAPA OBRA'!$B:$B,0))="x",'ETAPA OBRA'!M$1&", ","")& IF(INDEX('ETAPA OBRA'!N:N,MATCH($B15,'ETAPA OBRA'!$B:$B,0))="x",'ETAPA OBRA'!N$1&", ","")& IF(INDEX('ETAPA OBRA'!O:O,MATCH($B15,'ETAPA OBRA'!$B:$B,0))="x",'ETAPA OBRA'!O$1&", ","")& IF(INDEX('ETAPA OBRA'!P:P,MATCH($B15,'ETAPA OBRA'!$B:$B,0))="x",'ETAPA OBRA'!P$1&", ","")& IF(INDEX('ETAPA OBRA'!Q:Q,MATCH($B15,'ETAPA OBRA'!$B:$B,0))="x",'ETAPA OBRA'!Q$1&", ","")& IF(INDEX('ETAPA OBRA'!R:R,MATCH($B15,'ETAPA OBRA'!$B:$B,0))="x",'ETAPA OBRA'!R$1&", ","")& IF(INDEX('ETAPA OBRA'!S:S,MATCH($B15,'ETAPA OBRA'!$B:$B,0))="x",'ETAPA OBRA'!S$1&", ","")& IF(INDEX('ETAPA OBRA'!T:T,MATCH($B15,'ETAPA OBRA'!$B:$B,0))="x",'ETAPA OBRA'!T$1&", ","")& IF(INDEX('ETAPA OBRA'!U:U,MATCH($B15,'ETAPA OBRA'!$B:$B,0))="x",'ETAPA OBRA'!U$1&", ","") )-2),"") -> Finalizado | N15: =IF(M15="","Não iniciada", IF(ISNUMBER(FIND("Cancelada",M15)),"Cancelada", IF(ISNUMBER(FIND("Paralisada",M15)),"Paralisada", IF(ISNUMBER(FIND("Finalizado",M15)),"Finalizado", "Em andamento")))) -> Finalizado | O15: 26432.8 | P15: =SUM($J15:$L15) -> 11871.47 | Q15: =O15-P15 -> 14561.33 | R15: =IF(O15=0,0,Q15/O15) -> 0.5508811 | S15: =IF(R15>=0.2,"✅ OK - Fechar Parceiro","⚠️ Ajustar Custos (<20%)") -> ✅ OK - Fechar Parceiro | T15: =Cronograma[[#This Row],[STATUS]] -> ✅ CONCLUÍDO
